<sdf version='1.6'>
  <world name='default'>
    <light name='sun' type='directional'>
      <cast_shadows>1</cast_shadows>
      <pose frame=''>0 0 10 0 -0 0</pose>
      <diffuse>0.8 0.8 0.8 1</diffuse>
      <specular>0.1 0.1 0.1 1</specular>
      <attenuation>
        <range>1000</range>
        <constant>0.9</constant>
        <linear>0.01</linear>
        <quadratic>0.001</quadratic>
      </attenuation>
      <direction>-0.5 0.5 -1</direction>
    </light>
    <model name='ground_plane'>
      <static>1</static>
      <link name='link'>
        <collision name='collision'>
          <geometry>
            <plane>
              <normal>0 0 1</normal>
              <size>100 100</size>
            </plane>
          </geometry>
          <surface>
            <friction>
              <ode>
                <mu>100</mu>
                <mu2>50</mu2>
              </ode>
              <torsional>
                <ode/>
              </torsional>
            </friction>
            <contact>
              <ode/>
            </contact>
            <bounce/>
          </surface>
          <max_contacts>10</max_contacts>
        </collision>
        <visual name='visual'>
          <cast_shadows>0</cast_shadows>
          <geometry>
            <plane>
              <normal>0 0 1</normal>
              <size>100 100</size>
            </plane>
          </geometry>
          <material>
            <script>
              <uri>file://media/materials/scripts/gazebo.material</uri>
              <name>Gazebo/Grey</name>
            </script>
          </material>
        </visual>
        <self_collide>0</self_collide>
        <kinematic>0</kinematic>
        <gravity>1</gravity>
      </link>
    </model>
    <physics name='default_physics' default='0' type='ode'>
      <max_step_size>0.01</max_step_size>
      <real_time_factor>1</real_time_factor>
      <real_time_update_rate>100</real_time_update_rate>
    </physics>
    <gravity>0 0 -9.8</gravity>
    <magnetic_field>6e-06 2.3e-05 -4.2e-05</magnetic_field>
    <atmosphere type='adiabatic'/>
    <scene>
      <ambient>0.4 0.4 0.4 1</ambient>
      <background>0.7 0.7 0.7 1</background>
      <shadows>1</shadows>
    </scene>
    <spherical_coordinates>
      <surface_model>EARTH_WGS84</surface_model>
      <latitude_deg>0</latitude_deg>
      <longitude_deg>0</longitude_deg>
      <elevation>0</elevation>
      <heading_deg>0</heading_deg>
    </spherical_coordinates>
    <model name='mobile_base'>
      <link name='base_footprint'>
        <pose frame=''>0 0 0 0 -0 0</pose>
        <inertial>
          <pose frame=''>-0.002635 -4.1e-05 0.129243 0 -0 0</pose>
          <mass>4.6973</mass>
          <inertia>
            <ixx>0.1365</ixx>
            <ixy>-2.51802e-05</ixy>
            <ixz>0.0108194</ixz>
            <iyy>0.132157</iyy>
            <iyz>4.89572e-05</iyz>
            <izz>0.0741648</izz>
          </inertia>
        </inertial>
        <collision name='base_footprint_fixed_joint_lump__base_collision'>
          <pose frame=''>0 0 0.06969 0 -0 0</pose>
          <geometry>
            <cylinder>
              <length>0.10938</length>
              <radius>0.178</radius>
            </cylinder>
          </geometry>
          <max_contacts>10</max_contacts>
          <surface>
            <contact>
              <ode/>
            </contact>
            <bounce/>
            <friction>
              <torsional>
                <ode/>
              </torsional>
              <ode/>
            </friction>
          </surface>
        </collision>
        <collision name='base_footprint_fixed_joint_lump__camera_link_collision_1'>
          <pose frame=''>-0.087 -0.0015 0.2972 0 -0 0</pose>
          <geometry>
            <box>
              <size>0.073 0.276 0.072</size>
            </box>
          </geometry>
          <surface>
            <contact>
              <ode/>
            </contact>
            <friction>
              <ode/>
              <torsional>
                <ode/>
              </torsional>
            </friction>
            <bounce/>
          </surface>
          <max_contacts>10</max_contacts>
        </collision>
        <collision name='base_footprint_fixed_joint_lump__caster_back_link_collision_2'>
          <pose frame=''>-0.135 0 0.0192 -1.5708 0 0</pose>
          <geometry>
            <cylinder>
              <length>0.0176</length>
              <radius>0.017</radius>
            </cylinder>
          </geometry>
          <surface>
            <contact>
              <ode>
                <kp>1e+06</kp>
                <kd>100</kd>
                <max_vel>1</max_vel>
                <min_depth>0.001</min_depth>
              </ode>
            </contact>
            <friction>
              <ode>
                <mu>0</mu>
                <mu2>0</mu2>
              </ode>
              <torsional>
                <ode/>
              </torsional>
            </friction>
            <bounce/>
          </surface>
          <max_contacts>10</max_contacts>
        </collision>
        <collision name='base_footprint_fixed_joint_lump__caster_front_link_collision_3'>
          <pose frame=''>0.115 0 0.0172 -1.5708 0 0</pose>
          <geometry>
            <cylinder>
              <length>0.0176</length>
              <radius>0.017</radius>
            </cylinder>
          </geometry>
          <surface>
            <contact>
              <ode>
                <kp>1e+06</kp>
                <kd>100</kd>
                <max_vel>1</max_vel>
                <min_depth>0.001</min_depth>
              </ode>
            </contact>
            <friction>
              <ode>
                <mu>0</mu>
                <mu2>0</mu2>
              </ode>
              <torsional>
                <ode/>
              </torsional>
            </friction>
            <bounce/>
          </surface>
          <max_contacts>10</max_contacts>
        </collision>
        <collision name='base_footprint_fixed_joint_lump__mount_asus_xtion_pro_link_collision_4'>
          <pose frame=''>-0.1024 0 0.2822 0 -0 0</pose>
          <geometry>
            <box>
              <size>0.033 0.276 0.012</size>
            </box>
          </geometry>
          <max_contacts>10</max_contacts>
          <surface>
            <contact>
              <ode/>
            </contact>
            <bounce/>
            <friction>
              <torsional>
                <ode/>
              </torsional>
              <ode/>
            </friction>
          </surface>
        </collision>
        <collision name='base_footprint_fixed_joint_lump__plate_bottom_link_collision_5'>
          <pose frame=''>0 0 0.1408 0 -0 0</pose>
          <geometry>
            <cylinder>
              <length>0.006</length>
              <radius>0.17</radius>
            </cylinder>
          </geometry>
          <max_contacts>10</max_contacts>
          <surface>
            <contact>
              <ode/>
            </contact>
            <bounce/>
            <friction>
              <torsional>
                <ode/>
              </torsional>
              <ode/>
            </friction>
          </surface>
        </collision>
        <collision name='base_footprint_fixed_joint_lump__plate_middle_link_collision_6'>
          <pose frame=''>0 0 0.1976 0 -0 0</pose>
          <geometry>
            <cylinder>
              <length>0.006</length>
              <radius>0.17</radius>
            </cylinder>
          </geometry>
          <max_contacts>10</max_contacts>
          <surface>
            <contact>
              <ode/>
            </contact>
            <bounce/>
            <friction>
              <torsional>
                <ode/>
              </torsional>
              <ode/>
            </friction>
          </surface>
        </collision>
        <collision name='base_footprint_fixed_joint_lump__plate_top_link_collision_7'>
          <pose frame=''>0 0 0.4068 0 -0 0</pose>
          <geometry>
            <cylinder>
              <length>0.006</length>
              <radius>0.17</radius>
            </cylinder>
          </geometry>
          <max_contacts>10</max_contacts>
          <surface>
            <contact>
              <ode/>
            </contact>
            <bounce/>
            <friction>
              <torsional>
                <ode/>
              </torsional>
              <ode/>
            </friction>
          </surface>
        </collision>
        <collision name='base_footprint_fixed_joint_lump__pole_bottom_0_link_collision_8'>
          <pose frame=''>0.12 0.082 0.113 0 -0 0</pose>
          <geometry>
            <cylinder>
              <length>0.0492</length>
              <radius>0.006</radius>
            </cylinder>
          </geometry>
          <max_contacts>10</max_contacts>
          <surface>
            <contact>
              <ode/>
            </contact>
            <bounce/>
            <friction>
              <torsional>
                <ode/>
              </torsional>
              <ode/>
            </friction>
          </surface>
        </collision>
        <collision name='base_footprint_fixed_joint_lump__pole_bottom_1_link_collision_9'>
          <pose frame=''>0.055 0.12 0.113 0 -0 0</pose>
          <geometry>
            <cylinder>
              <length>0.0492</length>
              <radius>0.006</radius>
            </cylinder>
          </geometry>
          <max_contacts>10</max_contacts>
          <surface>
            <contact>
              <ode/>
            </contact>
            <bounce/>
            <friction>
              <torsional>
                <ode/>
              </torsional>
              <ode/>
            </friction>
          </surface>
        </collision>
        <collision name='base_footprint_fixed_joint_lump__pole_bottom_2_link_collision_10'>
          <pose frame=''>-0.055 0.12 0.113 0 -0 0</pose>
          <geometry>
            <cylinder>
              <length>0.0492</length>
              <radius>0.006</radius>
            </cylinder>
          </geometry>
          <max_contacts>10</max_contacts>
          <surface>
            <contact>
              <ode/>
            </contact>
            <bounce/>
            <friction>
              <torsional>
                <ode/>
              </torsional>
              <ode/>
            </friction>
          </surface>
        </collision>
        <collision name='base_footprint_fixed_joint_lump__pole_bottom_3_link_collision_11'>
          <pose frame=''>0.12 -0.082 0.113 0 -0 0</pose>
          <geometry>
            <cylinder>
              <length>0.0492</length>
              <radius>0.006</radius>
            </cylinder>
          </geometry>
          <max_contacts>10</max_contacts>
          <surface>
            <contact>
              <ode/>
            </contact>
            <bounce/>
            <friction>
              <torsional>
                <ode/>
              </torsional>
              <ode/>
            </friction>
          </surface>
        </collision>
        <collision name='base_footprint_fixed_joint_lump__pole_bottom_4_link_collision_12'>
          <pose frame=''>0.055 -0.12 0.113 0 -0 0</pose>
          <geometry>
            <cylinder>
              <length>0.0492</length>
              <radius>0.006</radius>
            </cylinder>
          </geometry>
          <max_contacts>10</max_contacts>
          <surface>
            <contact>
              <ode/>
            </contact>
            <bounce/>
            <friction>
              <torsional>
                <ode/>
              </torsional>
              <ode/>
            </friction>
          </surface>
        </collision>
        <collision name='base_footprint_fixed_joint_lump__pole_bottom_5_link_collision_13'>
          <pose frame=''>-0.055 -0.12 0.113 0 -0 0</pose>
          <geometry>
            <cylinder>
              <length>0.0492</length>
              <radius>0.006</radius>
            </cylinder>
          </geometry>
          <max_contacts>10</max_contacts>
          <surface>
            <contact>
              <ode/>
            </contact>
            <bounce/>
            <friction>
              <torsional>
                <ode/>
              </torsional>
              <ode/>
            </friction>
          </surface>
        </collision>
        <collision name='base_footprint_fixed_joint_lump__pole_kinect_0_link_collision_14'>
          <pose frame=''>-0.1024 0.098 0.2474 0 -0 0</pose>
          <geometry>
            <cylinder>
              <length>0.0936</length>
              <radius>0.006</radius>
            </cylinder>
          </geometry>
          <max_contacts>10</max_contacts>
          <surface>
            <contact>
              <ode/>
            </contact>
            <bounce/>
            <friction>
              <torsional>
                <ode/>
              </torsional>
              <ode/>
            </friction>
          </surface>
        </collision>
        <collision name='base_footprint_fixed_joint_lump__pole_kinect_1_link_collision_15'>
          <pose frame=''>-0.1024 -0.098 0.2474 0 -0 0</pose>
          <geometry>
            <cylinder>
              <length>0.0936</length>
              <radius>0.006</radius>
            </cylinder>
          </geometry>
          <max_contacts>10</max_contacts>
          <surface>
            <contact>
              <ode/>
            </contact>
            <bounce/>
            <friction>
              <torsional>
                <ode/>
              </torsional>
              <ode/>
            </friction>
          </surface>
        </collision>
        <collision name='base_footprint_fixed_joint_lump__pole_middle_0_link_collision_16'>
          <pose frame=''>0.0381 0.1505 0.1742 0 -0 0</pose>
          <geometry>
            <cylinder>
              <length>0.0608</length>
              <radius>0.006</radius>
            </cylinder>
          </geometry>
          <max_contacts>10</max_contacts>
          <surface>
            <contact>
              <ode/>
            </contact>
            <bounce/>
            <friction>
              <torsional>
                <ode/>
              </torsional>
              <ode/>
            </friction>
          </surface>
        </collision>
        <collision name='base_footprint_fixed_joint_lump__pole_middle_1_link_collision_17'>
          <pose frame=''>0.0381 -0.1505 0.1742 0 -0 0</pose>
          <geometry>
            <cylinder>
              <length>0.0608</length>
              <radius>0.006</radius>
            </cylinder>
          </geometry>
          <max_contacts>10</max_contacts>
          <surface>
            <contact>
              <ode/>
            </contact>
            <bounce/>
            <friction>
              <torsional>
                <ode/>
              </torsional>
              <ode/>
            </friction>
          </surface>
        </collision>
        <collision name='base_footprint_fixed_joint_lump__pole_middle_2_link_collision_18'>
          <pose frame=''>-0.0381 0.1505 0.1742 0 -0 0</pose>
          <geometry>
            <cylinder>
              <length>0.0608</length>
              <radius>0.006</radius>
            </cylinder>
          </geometry>
          <max_contacts>10</max_contacts>
          <surface>
            <contact>
              <ode/>
            </contact>
            <bounce/>
            <friction>
              <torsional>
                <ode/>
              </torsional>
              <ode/>
            </friction>
          </surface>
        </collision>
        <collision name='base_footprint_fixed_joint_lump__pole_middle_3_link_collision_19'>
          <pose frame=''>-0.0381 -0.1505 0.1742 0 -0 0</pose>
          <geometry>
            <cylinder>
              <length>0.0608</length>
              <radius>0.006</radius>
            </cylinder>
          </geometry>
          <max_contacts>10</max_contacts>
          <surface>
            <contact>
              <ode/>
            </contact>
            <bounce/>
            <friction>
              <torsional>
                <ode/>
              </torsional>
              <ode/>
            </friction>
          </surface>
        </collision>
        <collision name='base_footprint_fixed_joint_lump__pole_top_0_link_collision_20'>
          <pose frame=''>0.0381 0.1505 0.3022 0 -0 0</pose>
          <geometry>
            <cylinder>
              <length>0.2032</length>
              <radius>0.006</radius>
            </cylinder>
          </geometry>
          <max_contacts>10</max_contacts>
          <surface>
            <contact>
              <ode/>
            </contact>
            <bounce/>
            <friction>
              <torsional>
                <ode/>
              </torsional>
              <ode/>
            </friction>
          </surface>
        </collision>
        <collision name='base_footprint_fixed_joint_lump__pole_top_1_link_collision_21'>
          <pose frame=''>0.0381 -0.1505 0.3022 0 -0 0</pose>
          <geometry>
            <cylinder>
              <length>0.2032</length>
              <radius>0.006</radius>
            </cylinder>
          </geometry>
          <max_contacts>10</max_contacts>
          <surface>
            <contact>
              <ode/>
            </contact>
            <bounce/>
            <friction>
              <torsional>
                <ode/>
              </torsional>
              <ode/>
            </friction>
          </surface>
        </collision>
        <collision name='base_footprint_fixed_joint_lump__pole_top_2_link_collision_22'>
          <pose frame=''>-0.0381 0.1505 0.3022 0 -0 0</pose>
          <geometry>
            <cylinder>
              <length>0.2032</length>
              <radius>0.006</radius>
            </cylinder>
          </geometry>
          <max_contacts>10</max_contacts>
          <surface>
            <contact>
              <ode/>
            </contact>
            <bounce/>
            <friction>
              <torsional>
                <ode/>
              </torsional>
              <ode/>
            </friction>
          </surface>
        </collision>
        <collision name='base_footprint_fixed_joint_lump__pole_top_3_link_collision_23'>
          <pose frame=''>-0.0381 -0.1505 0.3022 0 -0 0</pose>
          <geometry>
            <cylinder>
              <length>0.2032</length>
              <radius>0.006</radius>
            </cylinder>
          </geometry>
          <max_contacts>10</max_contacts>
          <surface>
            <contact>
              <ode/>
            </contact>
            <bounce/>
            <friction>
              <torsional>
                <ode/>
              </torsional>
              <ode/>
            </friction>
          </surface>
        </collision>
        <visual name='base_footprint_fixed_joint_lump__base_link_visual'>
          <pose frame=''>0.001 0 0.06219 0 -0 0</pose>
          <geometry>
            <mesh>
              <scale>1 1 1</scale>
              <uri>/opt/ros/kinetic/share/kobuki_description/meshes/main_body.dae</uri>
            </mesh>
          </geometry>
          <material>
            <script>
              <uri>__default__</uri>
              <name>__default__</name>
            </script>
          </material>
        </visual>
        <visual name='base_footprint_fixed_joint_lump__camera_link_visual_1'>
          <pose frame=''>-0.102 0.002 0.3012 0 -0 0</pose>
          <geometry>
            <mesh>
              <scale>1 1 1</scale>
              <uri>/opt/ros/kinetic/share/turtlebot_description/meshes/sensors/xtion_pro_camera.dae</uri>
            </mesh>
          </geometry>
          <material>
            <script>
              <uri>__default__</uri>
              <name>__default__</name>
            </script>
          </material>
        </visual>
        <visual name='base_footprint_fixed_joint_lump__mount_asus_xtion_pro_link_visual_2'>
          <pose frame=''>-0.1024 0 0.2822 -1.5708 0 0</pose>
          <geometry>
            <mesh>
              <scale>1 1 1</scale>
              <uri>/opt/ros/kinetic/share/turtlebot_description/meshes/sensors/xtion_pro_stack.dae</uri>
            </mesh>
          </geometry>
        </visual>
        <visual name='base_footprint_fixed_joint_lump__plate_bottom_link_visual_3'>
          <pose frame=''>0.02364 0 0.1408 0 -0 0</pose>
          <geometry>
            <mesh>
              <scale>1 1 1</scale>
              <uri>/opt/ros/kinetic/share/turtlebot_description/meshes/stacks/hexagons/plate_bottom.dae</uri>
            </mesh>
          </geometry>
        </visual>
        <visual name='base_footprint_fixed_joint_lump__plate_middle_link_visual_4'>
          <pose frame=''>-0.01364 0 0.1976 0 -0 0</pose>
          <geometry>
            <mesh>
              <scale>1 1 1</scale>
              <uri>/opt/ros/kinetic/share/turtlebot_description/meshes/stacks/hexagons/plate_middle.dae</uri>
            </mesh>
          </geometry>
        </visual>
        <visual name='base_footprint_fixed_joint_lump__plate_top_link_visual_5'>
          <pose frame=''>-0.01364 0 0.4068 0 -0 0</pose>
          <geometry>
            <mesh>
              <scale>1 1 1</scale>
              <uri>/opt/ros/kinetic/share/turtlebot_description/meshes/stacks/hexagons/plate_top.dae</uri>
            </mesh>
          </geometry>
        </visual>
        <visual name='base_footprint_fixed_joint_lump__pole_bottom_0_link_visual_6'>
          <pose frame=''>0.12 0.082 0.113 0 -0 0</pose>
          <geometry>
            <mesh>
              <scale>1 1 1</scale>
              <uri>/opt/ros/kinetic/share/turtlebot_description/meshes/stacks/hexagons/pole_bottom.dae</uri>
            </mesh>
          </geometry>
        </visual>
        <visual name='base_footprint_fixed_joint_lump__pole_bottom_1_link_visual_7'>
          <pose frame=''>0.055 0.12 0.113 0 -0 0</pose>
          <geometry>
            <mesh>
              <scale>1 1 1</scale>
              <uri>/opt/ros/kinetic/share/turtlebot_description/meshes/stacks/hexagons/pole_bottom.dae</uri>
            </mesh>
          </geometry>
        </visual>
        <visual name='base_footprint_fixed_joint_lump__pole_bottom_2_link_visual_8'>
          <pose frame=''>-0.055 0.12 0.113 0 -0 0</pose>
          <geometry>
            <mesh>
              <scale>1 1 1</scale>
              <uri>/opt/ros/kinetic/share/turtlebot_description/meshes/stacks/hexagons/pole_bottom.dae</uri>
            </mesh>
          </geometry>
        </visual>
        <visual name='base_footprint_fixed_joint_lump__pole_bottom_3_link_visual_9'>
          <pose frame=''>0.12 -0.082 0.113 0 -0 0</pose>
          <geometry>
            <mesh>
              <scale>1 1 1</scale>
              <uri>/opt/ros/kinetic/share/turtlebot_description/meshes/stacks/hexagons/pole_bottom.dae</uri>
            </mesh>
          </geometry>
        </visual>
        <visual name='base_footprint_fixed_joint_lump__pole_bottom_4_link_visual_10'>
          <pose frame=''>0.055 -0.12 0.113 0 -0 0</pose>
          <geometry>
            <mesh>
              <scale>1 1 1</scale>
              <uri>/opt/ros/kinetic/share/turtlebot_description/meshes/stacks/hexagons/pole_bottom.dae</uri>
            </mesh>
          </geometry>
        </visual>
        <visual name='base_footprint_fixed_joint_lump__pole_bottom_5_link_visual_11'>
          <pose frame=''>-0.055 -0.12 0.113 0 -0 0</pose>
          <geometry>
            <mesh>
              <scale>1 1 1</scale>
              <uri>/opt/ros/kinetic/share/turtlebot_description/meshes/stacks/hexagons/pole_bottom.dae</uri>
            </mesh>
          </geometry>
        </visual>
        <visual name='base_footprint_fixed_joint_lump__pole_kinect_0_link_visual_12'>
          <pose frame=''>-0.1024 0.098 0.2374 0 -0 0</pose>
          <geometry>
            <mesh>
              <scale>1 1 1</scale>
              <uri>/opt/ros/kinetic/share/turtlebot_description/meshes/sensors/sensor_pole.dae</uri>
            </mesh>
          </geometry>
        </visual>
        <visual name='base_footprint_fixed_joint_lump__pole_kinect_1_link_visual_13'>
          <pose frame=''>-0.1024 -0.098 0.2374 0 -0 0</pose>
          <geometry>
            <mesh>
              <scale>1 1 1</scale>
              <uri>/opt/ros/kinetic/share/turtlebot_description/meshes/sensors/sensor_pole.dae</uri>
            </mesh>
          </geometry>
        </visual>
        <visual name='base_footprint_fixed_joint_lump__pole_middle_0_link_visual_14'>
          <pose frame=''>0.0381 0.1505 0.1742 3.14159 -0 3.14159</pose>
          <geometry>
            <mesh>
              <scale>1 1 1</scale>
              <uri>/opt/ros/kinetic/share/turtlebot_description/meshes/stacks/hexagons/pole_middle.dae</uri>
            </mesh>
          </geometry>
        </visual>
        <visual name='base_footprint_fixed_joint_lump__pole_middle_1_link_visual_15'>
          <pose frame=''>0.0381 -0.1505 0.1742 3.14159 -0 3.14159</pose>
          <geometry>
            <mesh>
              <scale>1 1 1</scale>
              <uri>/opt/ros/kinetic/share/turtlebot_description/meshes/stacks/hexagons/pole_middle.dae</uri>
            </mesh>
          </geometry>
        </visual>
        <visual name='base_footprint_fixed_joint_lump__pole_middle_2_link_visual_16'>
          <pose frame=''>-0.0381 0.1505 0.1742 3.14159 -0 3.14159</pose>
          <geometry>
            <mesh>
              <scale>1 1 1</scale>
              <uri>/opt/ros/kinetic/share/turtlebot_description/meshes/stacks/hexagons/pole_middle.dae</uri>
            </mesh>
          </geometry>
        </visual>
        <visual name='base_footprint_fixed_joint_lump__pole_middle_3_link_visual_17'>
          <pose frame=''>-0.0381 -0.1505 0.1742 3.14159 -0 3.14159</pose>
          <geometry>
            <mesh>
              <scale>1 1 1</scale>
              <uri>/opt/ros/kinetic/share/turtlebot_description/meshes/stacks/hexagons/pole_middle.dae</uri>
            </mesh>
          </geometry>
        </visual>
        <visual name='base_footprint_fixed_joint_lump__pole_top_0_link_visual_18'>
          <pose frame=''>0.0381 0.1505 0.3022 0 -0 0</pose>
          <geometry>
            <mesh>
              <scale>1 1 1</scale>
              <uri>/opt/ros/kinetic/share/turtlebot_description/meshes/stacks/hexagons/pole_top.dae</uri>
            </mesh>
          </geometry>
        </visual>
        <visual name='base_footprint_fixed_joint_lump__pole_top_1_link_visual_19'>
          <pose frame=''>0.0381 -0.1505 0.3022 0 -0 0</pose>
          <geometry>
            <mesh>
              <scale>1 1 1</scale>
              <uri>/opt/ros/kinetic/share/turtlebot_description/meshes/stacks/hexagons/pole_top.dae</uri>
            </mesh>
          </geometry>
        </visual>
        <visual name='base_footprint_fixed_joint_lump__pole_top_2_link_visual_20'>
          <pose frame=''>-0.0381 0.1505 0.3022 0 -0 0</pose>
          <geometry>
            <mesh>
              <scale>1 1 1</scale>
              <uri>/opt/ros/kinetic/share/turtlebot_description/meshes/stacks/hexagons/pole_top.dae</uri>
            </mesh>
          </geometry>
        </visual>
        <visual name='base_footprint_fixed_joint_lump__pole_top_3_link_visual_21'>
          <pose frame=''>-0.0381 -0.1505 0.3022 0 -0 0</pose>
          <geometry>
            <mesh>
              <scale>1 1 1</scale>
              <uri>/opt/ros/kinetic/share/turtlebot_description/meshes/stacks/hexagons/pole_top.dae</uri>
            </mesh>
          </geometry>
        </visual>
        <velocity_decay/>
        <sensor name='bumpers' type='contact'>
          <always_on>1</always_on>
          <update_rate>50</update_rate>
          <visualize>1</visualize>
          <contact>
            <collision>base_footprint_fixed_joint_lump__base_collision</collision>
            <topic>__default_topic__</topic>
          </contact>
          <pose frame=''>0 0 0.0102 0 -0 0</pose>
        </sensor>
        <velocity_decay/>
        <sensor name='camera' type='depth'>
          <always_on>1</always_on>
          <update_rate>20</update_rate>
          <camera name='__default__'>
            <horizontal_fov>1.0472</horizontal_fov>
            <image>
              <format>B8G8R8</format>
              <width>640</width>
              <height>480</height>
            </image>
            <clip>
              <near>0.05</near>
              <far>8</far>
            </clip>
          </camera>
          <plugin name='kinect_camera_controller' filename='libgazebo_ros_openni_kinect.so'>
            <cameraName>camera</cameraName>
            <alwaysOn>true</alwaysOn>
            <updateRate>10</updateRate>
            <imageTopicName>rgb/image_raw</imageTopicName>
            <depthImageTopicName>depth/image_raw</depthImageTopicName>
            <pointCloudTopicName>depth/points</pointCloudTopicName>
            <cameraInfoTopicName>rgb/camera_info</cameraInfoTopicName>
            <depthImageCameraInfoTopicName>depth/camera_info</depthImageCameraInfoTopicName>
            <frameName>camera_depth_optical_frame</frameName>
            <baseline>0.1</baseline>
            <distortion_k1>0.0</distortion_k1>
            <distortion_k2>0.0</distortion_k2>
            <distortion_k3>0.0</distortion_k3>
            <distortion_t1>0.0</distortion_t1>
            <distortion_t2>0.0</distortion_t2>
            <pointCloudCutoff>0.4</pointCloudCutoff>
            <robotNamespace>/</robotNamespace>
          </plugin>
          <pose frame=''>-0.087 -0.0015 0.2972 0 -0 0</pose>
        </sensor>
        <velocity_decay/>
        <velocity_decay/>
        <velocity_decay/>
        <sensor name='cliff_sensor_front' type='ray'>
          <always_on>1</always_on>
          <update_rate>50</update_rate>
          <visualize>1</visualize>
          <ray>
            <scan>
              <horizontal>
                <samples>50</samples>
                <resolution>1</resolution>
                <min_angle>-0.0436</min_angle>
                <max_angle>0.0436</max_angle>
              </horizontal>
              <vertical>
                <samples>1</samples>
                <min_angle>0</min_angle>
                <max_angle>0</max_angle>
              </vertical>
            </scan>
            <range>
              <min>0.01</min>
              <max>0.15</max>
              <resolution>1</resolution>
            </range>
          </ray>
          <pose frame=''>0.156 0 0.0316 3.14159 1.57079 3.14159</pose>
        </sensor>
        <velocity_decay/>
        <sensor name='cliff_sensor_left' type='ray'>
          <always_on>1</always_on>
          <update_rate>50</update_rate>
          <visualize>1</visualize>
          <ray>
            <scan>
              <horizontal>
                <samples>50</samples>
                <resolution>1</resolution>
                <min_angle>-0.0436</min_angle>
                <max_angle>0.0436</max_angle>
              </horizontal>
              <vertical>
                <samples>1</samples>
                <min_angle>0</min_angle>
                <max_angle>0</max_angle>
              </vertical>
            </scan>
            <range>
              <min>0.01</min>
              <max>0.15</max>
              <resolution>1</resolution>
            </range>
          </ray>
          <pose frame=''>0.08734 0.13601 0.0316 3.14159 1.57079 3.14159</pose>
        </sensor>
        <velocity_decay/>
        <sensor name='cliff_sensor_right' type='ray'>
          <always_on>1</always_on>
          <update_rate>50</update_rate>
          <visualize>1</visualize>
          <ray>
            <scan>
              <horizontal>
                <samples>50</samples>
                <resolution>1</resolution>
                <min_angle>-0.0436</min_angle>
                <max_angle>0.0436</max_angle>
              </horizontal>
              <vertical>
                <samples>1</samples>
                <min_angle>0</min_angle>
                <max_angle>0</max_angle>
              </vertical>
            </scan>
            <range>
              <min>0.01</min>
              <max>0.15</max>
              <resolution>1</resolution>
            </range>
          </ray>
          <pose frame=''>0.085 -0.13601 0.0316 3.14159 1.57079 3.14159</pose>
        </sensor>
        <gravity>1</gravity>
        <velocity_decay/>
        <self_collide>0</self_collide>
        <sensor name='imu' type='imu'>
          <always_on>1</always_on>
          <update_rate>50</update_rate>
          <visualize>0</visualize>
          <imu>
            <angular_velocity>
              <x>
                <noise type='gaussian'>
                  <mean>0</mean>
                  <stddev>1.96e-06</stddev>
                  <bias_mean>0</bias_mean>
                  <bias_stddev>0</bias_stddev>
                </noise>
              </x>
              <y>
                <noise type='gaussian'>
                  <mean>0</mean>
                  <stddev>1.96e-06</stddev>
                  <bias_mean>0</bias_mean>
                  <bias_stddev>0</bias_stddev>
                </noise>
              </y>
              <z>
                <noise type='gaussian'>
                  <mean>0</mean>
                  <stddev>1.96e-06</stddev>
                  <bias_mean>0</bias_mean>
                  <bias_stddev>0</bias_stddev>
                </noise>
              </z>
            </angular_velocity>
            <linear_acceleration>
              <x>
                <noise type='gaussian'>
                  <mean>0</mean>
                  <stddev>0.017</stddev>
                  <bias_mean>0.1</bias_mean>
                  <bias_stddev>0.001</bias_stddev>
                </noise>
              </x>
              <y>
                <noise type='gaussian'>
                  <mean>0</mean>
                  <stddev>0.017</stddev>
                  <bias_mean>0.1</bias_mean>
                  <bias_stddev>0.001</bias_stddev>
                </noise>
              </y>
              <z>
                <noise type='gaussian'>
                  <mean>0</mean>
                  <stddev>0.017</stddev>
                  <bias_mean>0.1</bias_mean>
                  <bias_stddev>0.001</bias_stddev>
                </noise>
              </z>
            </linear_acceleration>
          </imu>
          <pose frame=''>0.056 0.062 0.0304 0 -0 0</pose>
        </sensor>
        <kinematic>0</kinematic>
      </link>
      <link name='wheel_left_link'>
        <pose frame=''>0 0.115 0.0352 -1.5708 0 0</pose>
        <inertial>
          <pose frame=''>0 0 0 0 -0 0</pose>
          <mass>0.01</mass>
          <inertia>
            <ixx>0.001</ixx>
            <ixy>0</ixy>
            <ixz>0</ixz>
            <iyy>0.001</iyy>
            <iyz>0</iyz>
            <izz>0.001</izz>
          </inertia>
        </inertial>
        <collision name='wheel_left_link_collision'>
          <pose frame=''>0 0 0 0 -0 0</pose>
          <geometry>
            <cylinder>
              <length>0.0206</length>
              <radius>0.0352</radius>
            </cylinder>
          </geometry>
          <surface>
            <contact>
              <ode>
                <kp>1e+06</kp>
                <kd>100</kd>
                <max_vel>1</max_vel>
                <min_depth>0.001</min_depth>
              </ode>
            </contact>
            <friction>
              <ode>
                <mu>1</mu>
                <mu2>1</mu2>
              </ode>
              <torsional>
                <ode/>
              </torsional>
            </friction>
            <bounce/>
          </surface>
          <max_contacts>10</max_contacts>
        </collision>
        <visual name='wheel_left_link_visual'>
          <pose frame=''>0 0 0 0 -0 0</pose>
          <geometry>
            <mesh>
              <scale>1 1 1</scale>
              <uri>/opt/ros/kinetic/share/kobuki_description/meshes/wheel.dae</uri>
            </mesh>
          </geometry>
          <material>
            <script>
              <uri>__default__</uri>
              <name>__default__</name>
            </script>
          </material>
        </visual>
        <gravity>1</gravity>
        <velocity_decay/>
        <self_collide>0</self_collide>
        <kinematic>0</kinematic>
      </link>
      <joint name='wheel_left_joint' type='revolute'>
        <child>wheel_left_link</child>
        <parent>base_footprint</parent>
        <axis>
          <xyz>0 1 0</xyz>
          <limit>
            <lower>-1e+16</lower>
            <upper>1e+16</upper>
          </limit>
          <dynamics>
            <spring_reference>0</spring_reference>
            <spring_stiffness>0</spring_stiffness>
          </dynamics>
          <use_parent_model_frame>1</use_parent_model_frame>
        </axis>
      </joint>
      <link name='wheel_right_link'>
        <pose frame=''>0 -0.115 0.0352 -1.5708 0 0</pose>
        <inertial>
          <pose frame=''>0 0 0 0 -0 0</pose>
          <mass>0.01</mass>
          <inertia>
            <ixx>0.001</ixx>
            <ixy>0</ixy>
            <ixz>0</ixz>
            <iyy>0.001</iyy>
            <iyz>0</iyz>
            <izz>0.001</izz>
          </inertia>
        </inertial>
        <collision name='wheel_right_link_collision'>
          <pose frame=''>0 0 0 0 -0 0</pose>
          <geometry>
            <cylinder>
              <length>0.0206</length>
              <radius>0.035</radius>
            </cylinder>
          </geometry>
          <surface>
            <contact>
              <ode>
                <kp>1e+06</kp>
                <kd>100</kd>
                <max_vel>1</max_vel>
                <min_depth>0.001</min_depth>
              </ode>
            </contact>
            <friction>
              <ode>
                <mu>1</mu>
                <mu2>1</mu2>
              </ode>
              <torsional>
                <ode/>
              </torsional>
            </friction>
            <bounce/>
          </surface>
          <max_contacts>10</max_contacts>
        </collision>
        <visual name='wheel_right_link_visual'>
          <pose frame=''>0 0 0 0 -0 0</pose>
          <geometry>
            <mesh>
              <scale>1 1 1</scale>
              <uri>/opt/ros/kinetic/share/kobuki_description/meshes/wheel.dae</uri>
            </mesh>
          </geometry>
          <material>
            <script>
              <uri>__default__</uri>
              <name>__default__</name>
            </script>
          </material>
        </visual>
        <gravity>1</gravity>
        <velocity_decay/>
        <self_collide>0</self_collide>
        <kinematic>0</kinematic>
      </link>
      <joint name='wheel_right_joint' type='revolute'>
        <child>wheel_right_link</child>
        <parent>base_footprint</parent>
        <axis>
          <xyz>0 1 0</xyz>
          <limit>
            <lower>-1e+16</lower>
            <upper>1e+16</upper>
          </limit>
          <dynamics>
            <spring_reference>0</spring_reference>
            <spring_stiffness>0</spring_stiffness>
          </dynamics>
          <use_parent_model_frame>1</use_parent_model_frame>
        </axis>
      </joint>
      <static>0</static>
      <plugin name='kobuki_controller' filename='libgazebo_ros_kobuki.so'>
        <publish_tf>1</publish_tf>
        <left_wheel_joint_name>wheel_left_joint</left_wheel_joint_name>
        <right_wheel_joint_name>wheel_right_joint</right_wheel_joint_name>
        <wheel_separation>.230</wheel_separation>
        <wheel_diameter>0.070</wheel_diameter>
        <torque>1.0</torque>
        <velocity_command_timeout>0.6</velocity_command_timeout>
        <cliff_sensor_left_name>cliff_sensor_left</cliff_sensor_left_name>
        <cliff_sensor_center_name>cliff_sensor_front</cliff_sensor_center_name>
        <cliff_sensor_right_name>cliff_sensor_right</cliff_sensor_right_name>
        <cliff_detection_threshold>0.04</cliff_detection_threshold>
        <bumper_name>bumpers</bumper_name>
        <imu_name>imu</imu_name>
        <robotNamespace>/</robotNamespace>
      </plugin>
      <pose frame=''>0 0 0 0 -0 0</pose>
    </model>
    <model name='grey_wall'>
      <static>1</static>
      <link name='link'>
        <pose frame=''>0 0 1.4 0 -0 0</pose>
        <collision name='collision'>
          <geometry>
            <box>
              <size>7.5 0.2 2.8</size>
            </box>
          </geometry>
          <max_contacts>10</max_contacts>
          <surface>
            <contact>
              <ode/>
            </contact>
            <bounce/>
            <friction>
              <torsional>
                <ode/>
              </torsional>
              <ode/>
            </friction>
          </surface>
        </collision>
        <visual name='visual'>
          <cast_shadows>0</cast_shadows>
          <geometry>
            <box>
              <size>7.5 0.2 2.8</size>
            </box>
          </geometry>
          <material>
            <script>
              <uri>model://grey_wall/materials/scripts</uri>
              <uri>model://grey_wall/materials/textures</uri>
              <name>vrc/grey_wall</name>
            </script>
          </material>
        </visual>
        <self_collide>0</self_collide>
        <kinematic>0</kinematic>
        <gravity>1</gravity>
      </link>
      <pose frame=''>-3.34398 9.61637 0 0 -0 0</pose>
    </model>
    <model name='grey_wall_clone'>
      <static>1</static>
      <link name='link'>
        <pose frame=''>0 0 1.4 0 -0 0</pose>
        <collision name='collision'>
          <geometry>
            <box>
              <size>7.5 0.2 2.8</size>
            </box>
          </geometry>
          <max_contacts>10</max_contacts>
          <surface>
            <contact>
              <ode/>
            </contact>
            <bounce/>
            <friction>
              <torsional>
                <ode/>
              </torsional>
              <ode/>
            </friction>
          </surface>
        </collision>
        <visual name='visual'>
          <cast_shadows>0</cast_shadows>
          <geometry>
            <box>
              <size>7.5 0.2 2.8</size>
            </box>
          </geometry>
          <material>
            <script>
              <uri>model://grey_wall/materials/scripts</uri>
              <uri>model://grey_wall/materials/textures</uri>
              <name>vrc/grey_wall</name>
            </script>
          </material>
        </visual>
        <self_collide>0</self_collide>
        <kinematic>0</kinematic>
        <gravity>1</gravity>
      </link>
      <pose frame=''>4.15067 9.58036 0 0 -0 0</pose>
    </model>
    <model name='grey_wall_clone_0'>
      <static>1</static>
      <link name='link'>
        <pose frame=''>0 0 1.4 0 -0 0</pose>
        <collision name='collision'>
          <geometry>
            <box>
              <size>7.5 0.2 2.8</size>
            </box>
          </geometry>
          <max_contacts>10</max_contacts>
          <surface>
            <contact>
              <ode/>
            </contact>
            <bounce/>
            <friction>
              <torsional>
                <ode/>
              </torsional>
              <ode/>
            </friction>
          </surface>
        </collision>
        <visual name='visual'>
          <cast_shadows>0</cast_shadows>
          <geometry>
            <box>
              <size>7.5 0.2 2.8</size>
            </box>
          </geometry>
          <material>
            <script>
              <uri>model://grey_wall/materials/scripts</uri>
              <uri>model://grey_wall/materials/textures</uri>
              <name>vrc/grey_wall</name>
            </script>
          </material>
        </visual>
        <self_collide>0</self_collide>
        <kinematic>0</kinematic>
        <gravity>1</gravity>
      </link>
      <pose frame=''>-2.93091 -7.79849 0 0 -0 0</pose>
    </model>
    <model name='grey_wall_clone_1'>
      <static>1</static>
      <link name='link'>
        <pose frame=''>0 0 1.4 0 -0 0</pose>
        <collision name='collision'>
          <geometry>
            <box>
              <size>7.5 0.2 2.8</size>
            </box>
          </geometry>
          <max_contacts>10</max_contacts>
          <surface>
            <contact>
              <ode/>
            </contact>
            <bounce/>
            <friction>
              <torsional>
                <ode/>
              </torsional>
              <ode/>
            </friction>
          </surface>
        </collision>
        <visual name='visual'>
          <cast_shadows>0</cast_shadows>
          <geometry>
            <box>
              <size>7.5 0.2 2.8</size>
            </box>
          </geometry>
          <material>
            <script>
              <uri>model://grey_wall/materials/scripts</uri>
              <uri>model://grey_wall/materials/textures</uri>
              <name>vrc/grey_wall</name>
            </script>
          </material>
        </visual>
        <self_collide>0</self_collide>
        <kinematic>0</kinematic>
        <gravity>1</gravity>
      </link>
      <pose frame=''>4.54523 -7.78553 0 0 -0 0</pose>
    </model>
    <model name='grey_wall_clone_2'>
      <static>1</static>
      <link name='link'>
        <pose frame=''>0 0 1.4 0 -0 0</pose>
        <collision name='collision'>
          <geometry>
            <box>
              <size>7.5 0.2 2.8</size>
            </box>
          </geometry>
          <max_contacts>10</max_contacts>
          <surface>
            <contact>
              <ode/>
            </contact>
            <bounce/>
            <friction>
              <torsional>
                <ode/>
              </torsional>
              <ode/>
            </friction>
          </surface>
        </collision>
        <visual name='visual'>
          <cast_shadows>0</cast_shadows>
          <geometry>
            <box>
              <size>7.5 0.2 2.8</size>
            </box>
          </geometry>
          <material>
            <script>
              <uri>model://grey_wall/materials/scripts</uri>
              <uri>model://grey_wall/materials/textures</uri>
              <name>vrc/grey_wall</name>
            </script>
          </material>
        </visual>
        <self_collide>0</self_collide>
        <kinematic>0</kinematic>
        <gravity>1</gravity>
      </link>
      <pose frame=''>5.85231 -2.95069 0 0 -0 0</pose>
    </model>
    <model name='grey_wall_clone_2_clone'>
      <static>1</static>
      <link name='link'>
        <pose frame=''>0 0 1.4 0 -0 0</pose>
        <collision name='collision'>
          <geometry>
            <box>
              <size>7.5 0.2 2.8</size>
            </box>
          </geometry>
          <max_contacts>10</max_contacts>
          <surface>
            <contact>
              <ode/>
            </contact>
            <bounce/>
            <friction>
              <torsional>
                <ode/>
              </torsional>
              <ode/>
            </friction>
          </surface>
        </collision>
        <visual name='visual'>
          <cast_shadows>0</cast_shadows>
          <geometry>
            <box>
              <size>7.5 0.2 2.8</size>
            </box>
          </geometry>
          <material>
            <script>
              <uri>model://grey_wall/materials/scripts</uri>
              <uri>model://grey_wall/materials/textures</uri>
              <name>vrc/grey_wall</name>
            </script>
          </material>
        </visual>
        <self_collide>0</self_collide>
        <kinematic>0</kinematic>
        <gravity>1</gravity>
      </link>
      <pose frame=''>7.88421 3.70626 0 0 -0 1.57591</pose>
    </model>
    <model name='grey_wall_clone_2_clone_0'>
      <static>1</static>
      <link name='link'>
        <pose frame=''>0 0 1.4 0 -0 0</pose>
        <collision name='collision'>
          <geometry>
            <box>
              <size>7.5 0.2 2.8</size>
            </box>
          </geometry>
          <max_contacts>10</max_contacts>
          <surface>
            <contact>
              <ode/>
            </contact>
            <bounce/>
            <friction>
              <torsional>
                <ode/>
              </torsional>
              <ode/>
            </friction>
          </surface>
        </collision>
        <visual name='visual'>
          <cast_shadows>0</cast_shadows>
          <geometry>
            <box>
              <size>7.5 0.2 2.8</size>
            </box>
          </geometry>
          <material>
            <script>
              <uri>model://grey_wall/materials/scripts</uri>
              <uri>model://grey_wall/materials/textures</uri>
              <name>vrc/grey_wall</name>
            </script>
          </material>
        </visual>
        <self_collide>0</self_collide>
        <kinematic>0</kinematic>
        <gravity>1</gravity>
      </link>
      <pose frame=''>-6.2653 4.14195 0 0 -0 1.57591</pose>
    </model>
    <model name='grey_wall_clone_2_clone_1'>
      <static>1</static>
      <link name='link'>
        <pose frame=''>0 0 1.4 0 -0 0</pose>
        <collision name='collision'>
          <geometry>
            <box>
              <size>7.5 0.2 2.8</size>
            </box>
          </geometry>
          <max_contacts>10</max_contacts>
          <surface>
            <contact>
              <ode/>
            </contact>
            <bounce/>
            <friction>
              <torsional>
                <ode/>
              </torsional>
              <ode/>
            </friction>
          </surface>
        </collision>
        <visual name='visual'>
          <cast_shadows>0</cast_shadows>
          <geometry>
            <box>
              <size>7.5 0.2 2.8</size>
            </box>
          </geometry>
          <material>
            <script>
              <uri>model://grey_wall/materials/scripts</uri>
              <uri>model://grey_wall/materials/textures</uri>
              <name>vrc/grey_wall</name>
            </script>
          </material>
        </visual>
        <self_collide>0</self_collide>
        <kinematic>0</kinematic>
        <gravity>1</gravity>
      </link>
      <pose frame=''>-6.21275 -3.07003 0 0 -0 1.57591</pose>
    </model>
    <model name='jersey_barrier'>
      <static>1</static>
      <link name='link'>
        <visual name='visual'>
          <geometry>
            <mesh>
              <uri>model://jersey_barrier/meshes/jersey_barrier.dae</uri>
              <scale>1 1 1</scale>
            </mesh>
          </geometry>
        </visual>
        <collision name='upright'>
          <pose frame=''>0 0 0.5715 0 -0 0</pose>
          <geometry>
            <box>
              <size>4.06542 0.3063 1.143</size>
            </box>
          </geometry>
          <max_contacts>10</max_contacts>
          <surface>
            <contact>
              <ode/>
            </contact>
            <bounce/>
            <friction>
              <torsional>
                <ode/>
              </torsional>
              <ode/>
            </friction>
          </surface>
        </collision>
        <collision name='base'>
          <pose frame=''>0 0 0.032258 0 -0 0</pose>
          <geometry>
            <box>
              <size>4.06542 0.8107 0.064516</size>
            </box>
          </geometry>
          <max_contacts>10</max_contacts>
          <surface>
            <contact>
              <ode/>
            </contact>
            <bounce/>
            <friction>
              <torsional>
                <ode/>
              </torsional>
              <ode/>
            </friction>
          </surface>
        </collision>
        <collision name='base2'>
          <pose frame=''>0 0 0.1 0 -0 0</pose>
          <geometry>
            <box>
              <size>4.06542 0.65 0.1</size>
            </box>
          </geometry>
          <max_contacts>10</max_contacts>
          <surface>
            <contact>
              <ode/>
            </contact>
            <bounce/>
            <friction>
              <torsional>
                <ode/>
              </torsional>
              <ode/>
            </friction>
          </surface>
        </collision>
        <collision name='base3'>
          <pose frame=''>0 0 0.2 0 -0 0</pose>
          <geometry>
            <box>
              <size>4.06542 0.5 0.1</size>
            </box>
          </geometry>
          <max_contacts>10</max_contacts>
          <surface>
            <contact>
              <ode/>
            </contact>
            <bounce/>
            <friction>
              <torsional>
                <ode/>
              </torsional>
              <ode/>
            </friction>
          </surface>
        </collision>
        <collision name='left-angle'>
          <pose frame=''>0 -0.224 0.2401 0.9 -0 0</pose>
          <geometry>
            <box>
              <size>4.06542 0.5 0.064516</size>
            </box>
          </geometry>
          <max_contacts>10</max_contacts>
          <surface>
            <contact>
              <ode/>
            </contact>
            <bounce/>
            <friction>
              <torsional>
                <ode/>
              </torsional>
              <ode/>
            </friction>
          </surface>
        </collision>
        <collision name='right-angle'>
          <pose frame=''>0 0.224 0.2401 -0.9 0 0</pose>
          <geometry>
            <box>
              <size>4.06542 0.5 0.064516</size>
            </box>
          </geometry>
          <max_contacts>10</max_contacts>
          <surface>
            <contact>
              <ode/>
            </contact>
            <bounce/>
            <friction>
              <torsional>
                <ode/>
              </torsional>
              <ode/>
            </friction>
          </surface>
        </collision>
        <self_collide>0</self_collide>
        <kinematic>0</kinematic>
        <gravity>1</gravity>
      </link>
      <pose frame=''>5.16022 7.30873 0 0 -0 0</pose>
    </model>
    <model name='jersey_barrier_clone'>
      <static>1</static>
      <link name='link'>
        <visual name='visual'>
          <geometry>
            <mesh>
              <uri>model://jersey_barrier/meshes/jersey_barrier.dae</uri>
              <scale>1 1 1</scale>
            </mesh>
          </geometry>
        </visual>
        <collision name='upright'>
          <pose frame=''>0 0 0.5715 0 -0 0</pose>
          <geometry>
            <box>
              <size>4.06542 0.3063 1.143</size>
            </box>
          </geometry>
          <max_contacts>10</max_contacts>
          <surface>
            <contact>
              <ode/>
            </contact>
            <bounce/>
            <friction>
              <torsional>
                <ode/>
              </torsional>
              <ode/>
            </friction>
          </surface>
        </collision>
        <collision name='base'>
          <pose frame=''>0 0 0.032258 0 -0 0</pose>
          <geometry>
            <box>
              <size>4.06542 0.8107 0.064516</size>
            </box>
          </geometry>
          <max_contacts>10</max_contacts>
          <surface>
            <contact>
              <ode/>
            </contact>
            <bounce/>
            <friction>
              <torsional>
                <ode/>
              </torsional>
              <ode/>
            </friction>
          </surface>
        </collision>
        <collision name='base2'>
          <pose frame=''>0 0 0.1 0 -0 0</pose>
          <geometry>
            <box>
              <size>4.06542 0.65 0.1</size>
            </box>
          </geometry>
          <max_contacts>10</max_contacts>
          <surface>
            <contact>
              <ode/>
            </contact>
            <bounce/>
            <friction>
              <torsional>
                <ode/>
              </torsional>
              <ode/>
            </friction>
          </surface>
        </collision>
        <collision name='base3'>
          <pose frame=''>0 0 0.2 0 -0 0</pose>
          <geometry>
            <box>
              <size>4.06542 0.5 0.1</size>
            </box>
          </geometry>
          <max_contacts>10</max_contacts>
          <surface>
            <contact>
              <ode/>
            </contact>
            <bounce/>
            <friction>
              <torsional>
                <ode/>
              </torsional>
              <ode/>
            </friction>
          </surface>
        </collision>
        <collision name='left-angle'>
          <pose frame=''>0 -0.224 0.2401 0.9 -0 0</pose>
          <geometry>
            <box>
              <size>4.06542 0.5 0.064516</size>
            </box>
          </geometry>
          <max_contacts>10</max_contacts>
          <surface>
            <contact>
              <ode/>
            </contact>
            <bounce/>
            <friction>
              <torsional>
                <ode/>
              </torsional>
              <ode/>
            </friction>
          </surface>
        </collision>
        <collision name='right-angle'>
          <pose frame=''>0 0.224 0.2401 -0.9 0 0</pose>
          <geometry>
            <box>
              <size>4.06542 0.5 0.064516</size>
            </box>
          </geometry>
          <max_contacts>10</max_contacts>
          <surface>
            <contact>
              <ode/>
            </contact>
            <bounce/>
            <friction>
              <torsional>
                <ode/>
              </torsional>
              <ode/>
            </friction>
          </surface>
        </collision>
        <self_collide>0</self_collide>
        <kinematic>0</kinematic>
        <gravity>1</gravity>
      </link>
      <pose frame=''>-5.52841 -5.96567 0 0 0 -0.908894</pose>
    </model>
    <model name='polaris_ranger_ev'>
      <link name='chassis'>
        <inertial>
          <mass>720</mass>
          <inertia>
            <ixx>140</ixx>
            <ixy>0</ixy>
            <iyy>550</iyy>
            <ixz>0</ixz>
            <iyz>0</iyz>
            <izz>550</izz>
          </inertia>
        </inertial>
        <visual name='visual'>
          <pose frame=''>0 0 0 0 0 -1.5708</pose>
          <geometry>
            <mesh>
              <uri>model://polaris_ranger_ev/meshes/polaris.dae</uri>
              <scale>1 1 1</scale>
            </mesh>
          </geometry>
          <material>
            <script>
              <uri>model://polaris_ranger_ev/materials/scripts</uri>
              <uri>model://polaris_ranger_ev/materials/textures</uri>
              <name>Polaris/Diffuse</name>
            </script>
          </material>
        </visual>
        <collision name='chassis_bottom'>
          <pose frame=''>0 0 0.35 0 -0 0</pose>
          <geometry>
            <box>
              <size>2 1 0.1</size>
            </box>
          </geometry>
          <max_contacts>10</max_contacts>
          <surface>
            <contact>
              <ode/>
            </contact>
            <bounce/>
            <friction>
              <torsional>
                <ode/>
              </torsional>
              <ode/>
            </friction>
          </surface>
        </collision>
        <collision name='cargo_bottom'>
          <pose frame=''>-0.9 0 0.9 0 -0 0</pose>
          <geometry>
            <box>
              <size>0.9 1.2 0.01</size>
            </box>
          </geometry>
          <max_contacts>10</max_contacts>
          <surface>
            <contact>
              <ode/>
            </contact>
            <bounce/>
            <friction>
              <torsional>
                <ode/>
              </torsional>
              <ode/>
            </friction>
          </surface>
        </collision>
        <collision name='cargo_front'>
          <pose frame=''>-0.45 0 1.025 0 -0 0</pose>
          <geometry>
            <box>
              <size>0.05 1.2 0.25</size>
            </box>
          </geometry>
          <max_contacts>10</max_contacts>
          <surface>
            <contact>
              <ode/>
            </contact>
            <bounce/>
            <friction>
              <torsional>
                <ode/>
              </torsional>
              <ode/>
            </friction>
          </surface>
        </collision>
        <collision name='cargo_back'>
          <pose frame=''>-1.35 0 1.025 0 -0 0</pose>
          <geometry>
            <box>
              <size>0.05 1.2 0.25</size>
            </box>
          </geometry>
          <max_contacts>10</max_contacts>
          <surface>
            <contact>
              <ode/>
            </contact>
            <bounce/>
            <friction>
              <torsional>
                <ode/>
              </torsional>
              <ode/>
            </friction>
          </surface>
        </collision>
        <collision name='cargo_left'>
          <pose frame=''>-0.9 0.6 1.025 0 -0 0</pose>
          <geometry>
            <box>
              <size>0.9 0.05 0.25</size>
            </box>
          </geometry>
          <max_contacts>10</max_contacts>
          <surface>
            <contact>
              <ode/>
            </contact>
            <bounce/>
            <friction>
              <torsional>
                <ode/>
              </torsional>
              <ode/>
            </friction>
          </surface>
        </collision>
        <collision name='cargo_right'>
          <pose frame=''>-0.9 -0.6 1.025 0 -0 0</pose>
          <geometry>
            <box>
              <size>0.9 0.05 0.25</size>
            </box>
          </geometry>
          <max_contacts>10</max_contacts>
          <surface>
            <contact>
              <ode/>
            </contact>
            <bounce/>
            <friction>
              <torsional>
                <ode/>
              </torsional>
              <ode/>
            </friction>
          </surface>
        </collision>
        <collision name='seat'>
          <pose frame=''>-0.1 0 0.625 0 -0 0</pose>
          <geometry>
            <box>
              <size>0.6 1 0.65</size>
            </box>
          </geometry>
          <max_contacts>10</max_contacts>
          <surface>
            <contact>
              <ode/>
            </contact>
            <bounce/>
            <friction>
              <torsional>
                <ode/>
              </torsional>
              <ode/>
            </friction>
          </surface>
        </collision>
        <collision name='seat_back'>
          <pose frame=''>-0.3 0 1.125 0 -0.2 0</pose>
          <geometry>
            <box>
              <size>0.1 1 0.4</size>
            </box>
          </geometry>
          <max_contacts>10</max_contacts>
          <surface>
            <contact>
              <ode/>
            </contact>
            <bounce/>
            <friction>
              <torsional>
                <ode/>
              </torsional>
              <ode/>
            </friction>
          </surface>
        </collision>
        <collision name='engine'>
          <pose frame=''>0.95 0 0.7 0 -0 0</pose>
          <geometry>
            <box>
              <size>0.58 1 0.8</size>
            </box>
          </geometry>
          <max_contacts>10</max_contacts>
          <surface>
            <contact>
              <ode/>
            </contact>
            <bounce/>
            <friction>
              <torsional>
                <ode/>
              </torsional>
              <ode/>
            </friction>
          </surface>
        </collision>
        <collision name='steering_column'>
          <pose frame=''>0.525 0.3 1.025 0 -0.8 0</pose>
          <geometry>
            <cylinder>
              <radius>0.05</radius>
              <length>0.45</length>
            </cylinder>
          </geometry>
          <max_contacts>10</max_contacts>
          <surface>
            <contact>
              <ode/>
            </contact>
            <bounce/>
            <friction>
              <torsional>
                <ode/>
              </torsional>
              <ode/>
            </friction>
          </surface>
        </collision>
        <self_collide>0</self_collide>
        <kinematic>0</kinematic>
        <gravity>1</gravity>
      </link>
      <link name='rear_right_wheel'>
        <pose frame=''>-0.85 -0.6 0.32 1.5708 -0 0</pose>
        <inertial>
          <mass>12</mass>
          <inertia>
            <ixx>0.5</ixx>
            <ixy>0</ixy>
            <iyy>0.5</iyy>
            <ixz>0</ixz>
            <iyz>0</iyz>
            <izz>1</izz>
          </inertia>
        </inertial>
        <collision name='collision'>
          <geometry>
            <cylinder>
              <radius>0.32</radius>
              <length>0.23</length>
            </cylinder>
          </geometry>
          <surface>
            <friction>
              <ode>
                <mu>100000</mu>
                <mu2>100000</mu2>
                <slip1>0</slip1>
                <slip2>0</slip2>
              </ode>
              <torsional>
                <ode/>
              </torsional>
            </friction>
            <contact>
              <ode/>
            </contact>
            <bounce/>
          </surface>
          <max_contacts>10</max_contacts>
        </collision>
        <self_collide>0</self_collide>
        <kinematic>0</kinematic>
        <gravity>1</gravity>
      </link>
      <joint name='rear_right_wheel_joint' type='revolute'>
        <pose frame=''>0 0 -0.1 0 -0 0</pose>
        <child>rear_right_wheel</child>
        <parent>chassis</parent>
        <axis>
          <xyz>0 1 0</xyz>
          <use_parent_model_frame>1</use_parent_model_frame>
          <limit>
            <lower>-1e+16</lower>
            <upper>1e+16</upper>
          </limit>
          <dynamics>
            <spring_reference>0</spring_reference>
            <spring_stiffness>0</spring_stiffness>
          </dynamics>
        </axis>
        <physics>
          <ode>
            <limit>
              <cfm>0</cfm>
              <erp>0.9</erp>
            </limit>
          </ode>
        </physics>
      </joint>
      <link name='rear_left_wheel'>
        <pose frame=''>-0.85 0.6 0.32 1.5708 -0 0</pose>
        <inertial>
          <mass>12</mass>
          <inertia>
            <ixx>0.5</ixx>
            <ixy>0</ixy>
            <iyy>0.5</iyy>
            <ixz>0</ixz>
            <iyz>0</iyz>
            <izz>1</izz>
          </inertia>
        </inertial>
        <collision name='collision'>
          <geometry>
            <cylinder>
              <radius>0.32</radius>
              <length>0.23</length>
            </cylinder>
          </geometry>
          <surface>
            <friction>
              <ode>
                <mu>100000</mu>
                <mu2>100000</mu2>
                <slip1>0</slip1>
                <slip2>0</slip2>
              </ode>
              <torsional>
                <ode/>
              </torsional>
            </friction>
            <contact>
              <ode/>
            </contact>
            <bounce/>
          </surface>
          <max_contacts>10</max_contacts>
        </collision>
        <self_collide>0</self_collide>
        <kinematic>0</kinematic>
        <gravity>1</gravity>
      </link>
      <joint name='rear_left_wheel_joint' type='revolute'>
        <child>rear_left_wheel</child>
        <parent>chassis</parent>
        <axis>
          <xyz>0 1 0</xyz>
          <use_parent_model_frame>1</use_parent_model_frame>
          <limit>
            <lower>-1e+16</lower>
            <upper>1e+16</upper>
          </limit>
          <dynamics>
            <spring_reference>0</spring_reference>
            <spring_stiffness>0</spring_stiffness>
          </dynamics>
        </axis>
        <physics>
          <ode>
            <limit>
              <cfm>0</cfm>
              <erp>0.9</erp>
            </limit>
          </ode>
        </physics>
      </joint>
      <link name='front_right_wheel'>
        <pose frame=''>1.03 -0.6 0.32 1.5708 -0 0</pose>
        <inertial>
          <mass>12</mass>
          <inertia>
            <ixx>0.5</ixx>
            <ixy>0</ixy>
            <iyy>0.5</iyy>
            <ixz>0</ixz>
            <iyz>0</iyz>
            <izz>1</izz>
          </inertia>
        </inertial>
        <collision name='collision'>
          <geometry>
            <cylinder>
              <radius>0.32</radius>
              <length>0.23</length>
            </cylinder>
          </geometry>
          <surface>
            <friction>
              <ode>
                <mu>100000</mu>
                <mu2>100000</mu2>
                <slip1>0</slip1>
                <slip2>0</slip2>
              </ode>
              <torsional>
                <ode/>
              </torsional>
            </friction>
            <contact>
              <ode/>
            </contact>
            <bounce/>
          </surface>
          <max_contacts>10</max_contacts>
        </collision>
        <self_collide>0</self_collide>
        <kinematic>0</kinematic>
        <gravity>1</gravity>
      </link>
      <link name='front_right_wheel_steering_block'>
        <pose frame=''>1.03 -0.5 0.32 1.5708 -0 0</pose>
        <inertial>
          <mass>1</mass>
          <inertia>
            <ixx>1</ixx>
            <ixy>0</ixy>
            <iyy>1</iyy>
            <ixz>0</ixz>
            <iyz>0</iyz>
            <izz>1</izz>
          </inertia>
        </inertial>
        <collision name='collision'>
          <geometry>
            <cylinder>
              <radius>0.05</radius>
              <length>0.01</length>
            </cylinder>
          </geometry>
          <max_contacts>10</max_contacts>
          <surface>
            <contact>
              <ode/>
            </contact>
            <bounce/>
            <friction>
              <torsional>
                <ode/>
              </torsional>
              <ode/>
            </friction>
          </surface>
        </collision>
        <self_collide>0</self_collide>
        <kinematic>0</kinematic>
        <gravity>1</gravity>
      </link>
      <joint name='front_right_steering_joint' type='revolute'>
        <child>front_right_wheel_steering_block</child>
        <parent>chassis</parent>
        <axis>
          <xyz>0 0 1</xyz>
          <limit>
            <lower>-1</lower>
            <upper>1</upper>
          </limit>
          <use_parent_model_frame>1</use_parent_model_frame>
          <dynamics>
            <spring_reference>0</spring_reference>
            <spring_stiffness>0</spring_stiffness>
          </dynamics>
        </axis>
        <physics>
          <ode>
            <limit>
              <cfm>0</cfm>
              <erp>0.9</erp>
            </limit>
          </ode>
        </physics>
      </joint>
      <joint name='front_right_wheel_joint' type='revolute'>
        <child>front_right_wheel</child>
        <parent>front_right_wheel_steering_block</parent>
        <axis>
          <xyz>0 1 0</xyz>
          <use_parent_model_frame>1</use_parent_model_frame>
          <limit>
            <lower>-1e+16</lower>
            <upper>1e+16</upper>
          </limit>
          <dynamics>
            <spring_reference>0</spring_reference>
            <spring_stiffness>0</spring_stiffness>
          </dynamics>
        </axis>
        <physics>
          <ode>
            <limit>
              <cfm>0</cfm>
              <erp>0.9</erp>
            </limit>
          </ode>
        </physics>
      </joint>
      <link name='front_left_wheel'>
        <pose frame=''>1.03 0.6 0.32 1.5708 -0 0</pose>
        <inertial>
          <mass>12</mass>
          <inertia>
            <ixx>0.5</ixx>
            <ixy>0</ixy>
            <iyy>0.5</iyy>
            <ixz>0</ixz>
            <iyz>0</iyz>
            <izz>1</izz>
          </inertia>
        </inertial>
        <collision name='collision'>
          <geometry>
            <cylinder>
              <radius>0.32</radius>
              <length>0.23</length>
            </cylinder>
          </geometry>
          <surface>
            <friction>
              <ode>
                <mu>100000</mu>
                <mu2>100000</mu2>
                <slip1>0</slip1>
                <slip2>0</slip2>
              </ode>
              <torsional>
                <ode/>
              </torsional>
            </friction>
            <contact>
              <ode/>
            </contact>
            <bounce/>
          </surface>
          <max_contacts>10</max_contacts>
        </collision>
        <self_collide>0</self_collide>
        <kinematic>0</kinematic>
        <gravity>1</gravity>
      </link>
      <link name='front_left_wheel_steering_block'>
        <pose frame=''>1.03 0.5 0.32 1.5708 -0 0</pose>
        <inertial>
          <mass>1</mass>
          <inertia>
            <ixx>1</ixx>
            <ixy>0</ixy>
            <iyy>1</iyy>
            <ixz>0</ixz>
            <iyz>0</iyz>
            <izz>1</izz>
          </inertia>
        </inertial>
        <collision name='collision'>
          <geometry>
            <cylinder>
              <radius>0.05</radius>
              <length>0.01</length>
            </cylinder>
          </geometry>
          <max_contacts>10</max_contacts>
          <surface>
            <contact>
              <ode/>
            </contact>
            <bounce/>
            <friction>
              <torsional>
                <ode/>
              </torsional>
              <ode/>
            </friction>
          </surface>
        </collision>
        <self_collide>0</self_collide>
        <kinematic>0</kinematic>
        <gravity>1</gravity>
      </link>
      <joint name='front_left_steering_joint' type='revolute'>
        <child>front_left_wheel_steering_block</child>
        <parent>chassis</parent>
        <axis>
          <xyz>0 0 1</xyz>
          <limit>
            <lower>-1</lower>
            <upper>1</upper>
          </limit>
          <use_parent_model_frame>1</use_parent_model_frame>
          <dynamics>
            <spring_reference>0</spring_reference>
            <spring_stiffness>0</spring_stiffness>
          </dynamics>
        </axis>
        <physics>
          <ode>
            <limit>
              <cfm>0</cfm>
              <erp>0.9</erp>
            </limit>
          </ode>
        </physics>
      </joint>
      <joint name='front_left_wheel_joint' type='revolute'>
        <child>front_left_wheel</child>
        <parent>front_left_wheel_steering_block</parent>
        <axis>
          <xyz>0 1 0</xyz>
          <use_parent_model_frame>1</use_parent_model_frame>
          <limit>
            <lower>-1e+16</lower>
            <upper>1e+16</upper>
          </limit>
          <dynamics>
            <spring_reference>0</spring_reference>
            <spring_stiffness>0</spring_stiffness>
          </dynamics>
        </axis>
        <physics>
          <ode>
            <limit>
              <cfm>0</cfm>
              <erp>0.9</erp>
            </limit>
          </ode>
        </physics>
      </joint>
      <link name='gas_pedal'>
        <pose frame=''>0.53 0.14 0.56 0 -1 0</pose>
        <gravity>0</gravity>
        <inertial>
          <mass>0.1</mass>
          <pose frame=''>0 0 0 0 -0 0</pose>
          <inertia>
            <ixx>0.01</ixx>
            <ixy>0</ixy>
            <ixz>0</ixz>
            <iyy>0.01</iyy>
            <iyz>0</iyz>
            <izz>0.01</izz>
          </inertia>
        </inertial>
        <collision name='gas_pedal_collision'>
          <geometry>
            <box>
              <size>0.12 0.07 0.03</size>
            </box>
          </geometry>
          <max_contacts>10</max_contacts>
          <surface>
            <contact>
              <ode/>
            </contact>
            <bounce/>
            <friction>
              <torsional>
                <ode/>
              </torsional>
              <ode/>
            </friction>
          </surface>
        </collision>
        <visual name='gas_pedal_visual'>
          <geometry>
            <box>
              <size>0.12 0.07 0.03</size>
            </box>
          </geometry>
          <material>
            <script>
              <uri>file://media/materials/scripts/gazebo.material</uri>
              <name>Gazebo/Wood</name>
            </script>
            <ambient>0.2 0.2 0.2 1</ambient>
            <diffuse>0.2 0.2 0.2 1</diffuse>
            <specular>0.2 0.2 0.2 1</specular>
            <emissive>0.5 0.5 0.5 1</emissive>
          </material>
        </visual>
        <self_collide>0</self_collide>
        <kinematic>0</kinematic>
      </link>
      <link name='brake_pedal'>
        <gravity>0</gravity>
        <pose frame=''>0.54 0.27 0.58 0 -1 0</pose>
        <inertial>
          <mass>0.1</mass>
          <pose frame=''>0 0 0 0 -0 0</pose>
          <inertia>
            <ixx>0.01</ixx>
            <ixy>0</ixy>
            <ixz>0</ixz>
            <iyy>0.01</iyy>
            <iyz>0</iyz>
            <izz>0.01</izz>
          </inertia>
        </inertial>
        <collision name='brake_pedal_collision'>
          <geometry>
            <box>
              <size>0.06 0.08 0.03</size>
            </box>
          </geometry>
          <max_contacts>10</max_contacts>
          <surface>
            <contact>
              <ode/>
            </contact>
            <bounce/>
            <friction>
              <torsional>
                <ode/>
              </torsional>
              <ode/>
            </friction>
          </surface>
        </collision>
        <visual name='brake_pedal_visual'>
          <geometry>
            <box>
              <size>0.06 0.08 0.03</size>
            </box>
          </geometry>
          <material>
            <script>
              <uri>file://media/materials/scripts/gazebo.material</uri>
              <name>Gazebo/Wood</name>
            </script>
            <ambient>0.2 0.2 0.2 1</ambient>
            <diffuse>0.2 0.2 0.2 1</diffuse>
            <specular>0.2 0.2 0.2 1</specular>
            <emissive>0.5 0.5 0.5 1</emissive>
          </material>
        </visual>
        <self_collide>0</self_collide>
        <kinematic>0</kinematic>
      </link>
      <link name='steering_wheel'>
        <pose frame=''>0.37 0.3 1.2 0 -0.8 0</pose>
        <inertial>
          <mass>1</mass>
          <pose frame=''>0 0 0 0 -0 0</pose>
          <inertia>
            <ixx>0.1</ixx>
            <ixy>0</ixy>
            <ixz>0</ixz>
            <iyy>0.1</iyy>
            <iyz>0</iyz>
            <izz>1</izz>
          </inertia>
        </inertial>
        <collision name='steering_wheel_post_left'>
          <pose frame=''>0 0.08 0 1.5708 -0 0</pose>
          <geometry>
            <cylinder>
              <radius>0.02</radius>
              <length>0.15</length>
            </cylinder>
          </geometry>
          <max_contacts>10</max_contacts>
          <surface>
            <contact>
              <ode/>
            </contact>
            <bounce/>
            <friction>
              <torsional>
                <ode/>
              </torsional>
              <ode/>
            </friction>
          </surface>
        </collision>
        <collision name='steering_wheel_post_right'>
          <pose frame=''>0 -0.08 0 1.5708 -0 0</pose>
          <geometry>
            <cylinder>
              <radius>0.02</radius>
              <length>0.15</length>
            </cylinder>
          </geometry>
          <max_contacts>10</max_contacts>
          <surface>
            <contact>
              <ode/>
            </contact>
            <bounce/>
            <friction>
              <torsional>
                <ode/>
              </torsional>
              <ode/>
            </friction>
          </surface>
        </collision>
        <collision name='steering_wheel_post_middle'>
          <pose frame=''>-0.08 0 0 3.14159 1.57079 3.14159</pose>
          <geometry>
            <cylinder>
              <radius>0.02</radius>
              <length>0.15</length>
            </cylinder>
          </geometry>
          <max_contacts>10</max_contacts>
          <surface>
            <contact>
              <ode/>
            </contact>
            <bounce/>
            <friction>
              <torsional>
                <ode/>
              </torsional>
              <ode/>
            </friction>
          </surface>
        </collision>
        <collision name='collision00'>
          <pose frame=''>0.15 0 0 3.14159 1.57079 -1.57079</pose>
          <geometry>
            <cylinder>
              <length>0.105066</length>
              <radius>0.01</radius>
            </cylinder>
          </geometry>
          <max_contacts>10</max_contacts>
          <surface>
            <contact>
              <ode/>
            </contact>
            <bounce/>
            <friction>
              <torsional>
                <ode/>
              </torsional>
              <ode/>
            </friction>
          </surface>
        </collision>
        <collision name='collision01'>
          <pose frame=''>0.121353 0.088168 0 3.14159 1.57079 -0.942483</pose>
          <geometry>
            <cylinder>
              <length>0.105066</length>
              <radius>0.01</radius>
            </cylinder>
          </geometry>
          <max_contacts>10</max_contacts>
          <surface>
            <contact>
              <ode/>
            </contact>
            <bounce/>
            <friction>
              <torsional>
                <ode/>
              </torsional>
              <ode/>
            </friction>
          </surface>
        </collision>
        <collision name='collision02'>
          <pose frame=''>0.046353 0.142658 0 3.14159 1.57079 -0.314163</pose>
          <geometry>
            <cylinder>
              <length>0.105066</length>
              <radius>0.01</radius>
            </cylinder>
          </geometry>
          <max_contacts>10</max_contacts>
          <surface>
            <contact>
              <ode/>
            </contact>
            <bounce/>
            <friction>
              <torsional>
                <ode/>
              </torsional>
              <ode/>
            </friction>
          </surface>
        </collision>
        <collision name='collision03'>
          <pose frame=''>-0.046353 0.142658 0 3.14159 1.57079 0.314163</pose>
          <geometry>
            <cylinder>
              <length>0.105066</length>
              <radius>0.01</radius>
            </cylinder>
          </geometry>
          <max_contacts>10</max_contacts>
          <surface>
            <contact>
              <ode/>
            </contact>
            <bounce/>
            <friction>
              <torsional>
                <ode/>
              </torsional>
              <ode/>
            </friction>
          </surface>
        </collision>
        <collision name='collision04'>
          <pose frame=''>-0.121353 0.088168 0 -3.14159 1.57079 0.942483</pose>
          <geometry>
            <cylinder>
              <length>0.105066</length>
              <radius>0.01</radius>
            </cylinder>
          </geometry>
          <max_contacts>10</max_contacts>
          <surface>
            <contact>
              <ode/>
            </contact>
            <bounce/>
            <friction>
              <torsional>
                <ode/>
              </torsional>
              <ode/>
            </friction>
          </surface>
        </collision>
        <collision name='collision05'>
          <pose frame=''>-0.15 0 0 -3.14159 1.57079 1.57079</pose>
          <geometry>
            <cylinder>
              <length>0.105066</length>
              <radius>0.01</radius>
            </cylinder>
          </geometry>
          <max_contacts>10</max_contacts>
          <surface>
            <contact>
              <ode/>
            </contact>
            <bounce/>
            <friction>
              <torsional>
                <ode/>
              </torsional>
              <ode/>
            </friction>
          </surface>
        </collision>
        <collision name='collision06'>
          <pose frame=''>-0.121353 -0.088168 0 3.14159 1.57079 2.19912</pose>
          <geometry>
            <cylinder>
              <length>0.105066</length>
              <radius>0.01</radius>
            </cylinder>
          </geometry>
          <max_contacts>10</max_contacts>
          <surface>
            <contact>
              <ode/>
            </contact>
            <bounce/>
            <friction>
              <torsional>
                <ode/>
              </torsional>
              <ode/>
            </friction>
          </surface>
        </collision>
        <collision name='collision07'>
          <pose frame=''>-0.046353 -0.142658 0 -3.14159 1.57079 2.82743</pose>
          <geometry>
            <cylinder>
              <length>0.105066</length>
              <radius>0.01</radius>
            </cylinder>
          </geometry>
          <max_contacts>10</max_contacts>
          <surface>
            <contact>
              <ode/>
            </contact>
            <bounce/>
            <friction>
              <torsional>
                <ode/>
              </torsional>
              <ode/>
            </friction>
          </surface>
        </collision>
        <collision name='collision08'>
          <pose frame=''>0.046353 -0.142658 0 3.14159 1.57079 -2.82743</pose>
          <geometry>
            <cylinder>
              <length>0.105066</length>
              <radius>0.01</radius>
            </cylinder>
          </geometry>
          <max_contacts>10</max_contacts>
          <surface>
            <contact>
              <ode/>
            </contact>
            <bounce/>
            <friction>
              <torsional>
                <ode/>
              </torsional>
              <ode/>
            </friction>
          </surface>
        </collision>
        <collision name='collision09'>
          <pose frame=''>0.121353 -0.088168 0 -3.14159 1.57079 -2.19911</pose>
          <geometry>
            <cylinder>
              <length>0.105066</length>
              <radius>0.01</radius>
            </cylinder>
          </geometry>
          <max_contacts>10</max_contacts>
          <surface>
            <contact>
              <ode/>
            </contact>
            <bounce/>
            <friction>
              <torsional>
                <ode/>
              </torsional>
              <ode/>
            </friction>
          </surface>
        </collision>
        <self_collide>0</self_collide>
        <kinematic>0</kinematic>
        <gravity>1</gravity>
      </link>
      <link name='hand_brake'>
        <pose frame=''>0.5 0 1.05 3.14159 -0.058407 3.14159</pose>
        <inertial>
          <mass>1</mass>
          <pose frame=''>0 0 -0.15 0 -0 0</pose>
          <inertia>
            <ixx>0.1</ixx>
            <ixy>0</ixy>
            <ixz>0</ixz>
            <iyy>0.1</iyy>
            <iyz>0</iyz>
            <izz>1</izz>
          </inertia>
        </inertial>
        <collision name='hand_brake_collision'>
          <pose frame=''>0 0 -0.1 0 -0 0</pose>
          <geometry>
            <cylinder>
              <radius>0.01</radius>
              <length>0.2</length>
            </cylinder>
          </geometry>
          <max_contacts>10</max_contacts>
          <surface>
            <contact>
              <ode/>
            </contact>
            <bounce/>
            <friction>
              <torsional>
                <ode/>
              </torsional>
              <ode/>
            </friction>
          </surface>
        </collision>
        <visual name='hand_brake_visual'>
          <pose frame=''>0 0 -0.1 0 -0 0</pose>
          <geometry>
            <cylinder>
              <radius>0.01</radius>
              <length>0.2</length>
            </cylinder>
          </geometry>
          <material>
            <script>
              <uri>file://media/materials/scripts/gazebo.material</uri>
              <name>Gazebo/Wood</name>
            </script>
          </material>
        </visual>
        <self_collide>0</self_collide>
        <kinematic>0</kinematic>
        <gravity>1</gravity>
      </link>
      <joint name='gas_joint' type='prismatic'>
        <parent>chassis</parent>
        <child>gas_pedal</child>
        <axis>
          <xyz>1 0 -1</xyz>
          <limit>
            <lower>0</lower>
            <upper>0.15</upper>
          </limit>
          <use_parent_model_frame>1</use_parent_model_frame>
          <dynamics>
            <spring_reference>0</spring_reference>
            <spring_stiffness>0</spring_stiffness>
          </dynamics>
        </axis>
      </joint>
      <joint name='brake_joint' type='prismatic'>
        <parent>chassis</parent>
        <child>brake_pedal</child>
        <axis>
          <xyz>1 0 -0.6</xyz>
          <limit>
            <lower>0</lower>
            <upper>0.15</upper>
          </limit>
          <use_parent_model_frame>1</use_parent_model_frame>
          <dynamics>
            <spring_reference>0</spring_reference>
            <spring_stiffness>0</spring_stiffness>
          </dynamics>
        </axis>
      </joint>
      <joint name='steering_joint' type='revolute'>
        <pose frame=''>0 0 0 1.5708 -0.8 0</pose>
        <parent>chassis</parent>
        <child>steering_wheel</child>
        <axis>
          <xyz>-1 0 1.023</xyz>
          <limit>
            <lower>-7.853</lower>
            <upper>7.853</upper>
          </limit>
          <use_parent_model_frame>1</use_parent_model_frame>
          <dynamics>
            <spring_reference>0</spring_reference>
            <spring_stiffness>0</spring_stiffness>
          </dynamics>
        </axis>
      </joint>
      <joint name='hand_brake_joint' type='revolute'>
        <parent>chassis</parent>
        <child>hand_brake</child>
        <axis>
          <xyz>0 -1 0</xyz>
          <limit>
            <lower>0</lower>
            <upper>0.6</upper>
          </limit>
          <use_parent_model_frame>1</use_parent_model_frame>
          <dynamics>
            <spring_reference>0</spring_reference>
            <spring_stiffness>0</spring_stiffness>
          </dynamics>
        </axis>
      </joint>
      <pose frame=''>-0.467922 -5.1234 0 0 -0 0</pose>
    </model>
    <model name='brick_box_3x1x3'>
      <static>1</static>
      <link name='chassis'>
        <pose frame=''>0 0 1.5 0 -0 0</pose>
        <collision name='collision'>
          <geometry>
            <box>
              <size>3 1 3</size>
            </box>
          </geometry>
          <max_contacts>10</max_contacts>
          <surface>
            <contact>
              <ode/>
            </contact>
            <bounce/>
            <friction>
              <torsional>
                <ode/>
              </torsional>
              <ode/>
            </friction>
          </surface>
        </collision>
        <visual name='visual'>
          <geometry>
            <mesh>
              <uri>model://brick_box_3x1x3/meshes/simple_box.dae</uri>
              <scale>1 1 1</scale>
            </mesh>
          </geometry>
          <material>
            <script>
              <uri>model://brick_box_3x1x3/materials/scripts</uri>
              <uri>model://brick_box_3x1x3/materials/textures</uri>
              <name>BrickBox/Diffuse</name>
            </script>
          </material>
        </visual>
        <self_collide>0</self_collide>
        <kinematic>0</kinematic>
        <gravity>1</gravity>
      </link>
      <pose frame=''>4.01511 -2.96899 0 0 -0 0</pose>
    </model>
    <model name='Construction Barrel'>
      <static>1</static>
      <link name='link'>
        <inertial>
          <pose frame=''>0 0 0.4 0 -0 0</pose>
          <mass>500</mass>
          <inertia>
            <ixx>51.2096</ixx>
            <iyy>51.2096</iyy>
            <izz>25</izz>
            <ixy>0</ixy>
            <ixz>0</ixz>
            <iyz>0</iyz>
          </inertia>
        </inertial>
        <collision name='collision'>
          <geometry>
            <mesh>
              <uri>model://construction_barrel/meshes/construction_barrel.dae</uri>
              <scale>1 1 1</scale>
            </mesh>
          </geometry>
          <max_contacts>10</max_contacts>
          <surface>
            <contact>
              <ode/>
            </contact>
            <bounce/>
            <friction>
              <torsional>
                <ode/>
              </torsional>
              <ode/>
            </friction>
          </surface>
        </collision>
        <visual name='visual'>
          <geometry>
            <mesh>
              <uri>model://construction_barrel/meshes/construction_barrel.dae</uri>
              <scale>1 1 1</scale>
            </mesh>
          </geometry>
        </visual>
        <self_collide>0</self_collide>
        <kinematic>0</kinematic>
        <gravity>1</gravity>
      </link>
      <pose frame=''>-3.87735 3.24907 0 0 -0 0</pose>
    </model>
    <model name='Construction Barrel_0'>
      <static>1</static>
      <link name='link'>
        <inertial>
          <pose frame=''>0 0 0.4 0 -0 0</pose>
          <mass>500</mass>
          <inertia>
            <ixx>51.2096</ixx>
            <iyy>51.2096</iyy>
            <izz>25</izz>
            <ixy>0</ixy>
            <ixz>0</ixz>
            <iyz>0</iyz>
          </inertia>
        </inertial>
        <collision name='collision'>
          <geometry>
            <mesh>
              <uri>model://construction_barrel/meshes/construction_barrel.dae</uri>
              <scale>1 1 1</scale>
            </mesh>
          </geometry>
          <max_contacts>10</max_contacts>
          <surface>
            <contact>
              <ode/>
            </contact>
            <bounce/>
            <friction>
              <torsional>
                <ode/>
              </torsional>
              <ode/>
            </friction>
          </surface>
        </collision>
        <visual name='visual'>
          <geometry>
            <mesh>
              <uri>model://construction_barrel/meshes/construction_barrel.dae</uri>
              <scale>1 1 1</scale>
            </mesh>
          </geometry>
        </visual>
        <self_collide>0</self_collide>
        <kinematic>0</kinematic>
        <gravity>1</gravity>
      </link>
      <pose frame=''>-6.30148 8.91605 0 0 -0 0</pose>
    </model>
    <model name='Construction Cone'>
      <static>1</static>
      <link name='link'>
        <collision name='collision'>
          <geometry>
            <mesh>
              <scale>1 1 1</scale>
              <uri>model://construction_cone/meshes/construction_cone.dae</uri>
            </mesh>
          </geometry>
          <max_contacts>10</max_contacts>
          <surface>
            <contact>
              <ode/>
            </contact>
            <bounce/>
            <friction>
              <torsional>
                <ode/>
              </torsional>
              <ode/>
            </friction>
          </surface>
        </collision>
        <visual name='visual'>
          <geometry>
            <mesh>
              <scale>1 1 1</scale>
              <uri>model://construction_cone/meshes/construction_cone.dae</uri>
            </mesh>
          </geometry>
        </visual>
        <self_collide>0</self_collide>
        <kinematic>0</kinematic>
        <gravity>1</gravity>
      </link>
      <pose frame=''>5.2131 5.09331 0 0 -0 0</pose>
    </model>
    <model name='Construction Cone_0'>
      <static>1</static>
      <link name='link'>
        <collision name='collision'>
          <geometry>
            <mesh>
              <scale>1 1 1</scale>
              <uri>model://construction_cone/meshes/construction_cone.dae</uri>
            </mesh>
          </geometry>
          <max_contacts>10</max_contacts>
          <surface>
            <contact>
              <ode/>
            </contact>
            <bounce/>
            <friction>
              <torsional>
                <ode/>
              </torsional>
              <ode/>
            </friction>
          </surface>
        </collision>
        <visual name='visual'>
          <geometry>
            <mesh>
              <scale>1 1 1</scale>
              <uri>model://construction_cone/meshes/construction_cone.dae</uri>
            </mesh>
          </geometry>
        </visual>
        <self_collide>0</self_collide>
        <kinematic>0</kinematic>
        <gravity>1</gravity>
      </link>
      <pose frame=''>-4.0312 -3.93841 0 0 -0 0</pose>
    </model>
    <state world_name='default'>
      <sim_time>503 300000000</sim_time>
      <real_time>504 216103103</real_time>
      <wall_time>1573946056 863190197</wall_time>
      <iterations>50330</iterations>
      <model name='Construction Barrel'>
        <pose frame=''>-3.87735 3.24907 0 0 -0 0</pose>
        <scale>1 1 1</scale>
        <link name='link'>
          <pose frame=''>-3.87735 3.24907 0 0 -0 0</pose>
          <velocity>0 0 0 0 -0 0</velocity>
          <acceleration>0 0 0 0 -0 0</acceleration>
          <wrench>0 0 0 0 -0 0</wrench>
        </link>
      </model>
      <model name='Construction Barrel_0'>
        <pose frame=''>-6.30148 8.91605 0 0 -0 0</pose>
        <scale>1 1 1</scale>
        <link name='link'>
          <pose frame=''>-6.30148 8.91605 0 0 -0 0</pose>
          <velocity>0 0 0 0 -0 0</velocity>
          <acceleration>0 0 0 0 -0 0</acceleration>
          <wrench>0 0 0 0 -0 0</wrench>
        </link>
      </model>
      <model name='Construction Cone'>
        <pose frame=''>5.2131 5.09331 0 0 -0 0</pose>
        <scale>1 1 1</scale>
        <link name='link'>
          <pose frame=''>5.2131 5.09331 0 0 -0 0</pose>
          <velocity>0 0 0 0 -0 0</velocity>
          <acceleration>0 0 0 0 -0 0</acceleration>
          <wrench>0 0 0 0 -0 0</wrench>
        </link>
      </model>
      <model name='Construction Cone_0'>
        <pose frame=''>-4.0312 -3.93841 0 0 -0 0</pose>
        <scale>1 1 1</scale>
        <link name='link'>
          <pose frame=''>-4.0312 -3.93841 0 0 -0 0</pose>
          <velocity>0 0 0 0 -0 0</velocity>
          <acceleration>0 0 0 0 -0 0</acceleration>
          <wrench>0 0 0 0 -0 0</wrench>
        </link>
      </model>
      <model name='brick_box_3x1x3'>
        <pose frame=''>4.01511 -2.96899 0 0 -0 0</pose>
        <scale>1 1 1</scale>
        <link name='chassis'>
          <pose frame=''>4.01511 -2.96899 1.5 0 -0 0</pose>
          <velocity>0 0 0 0 -0 0</velocity>
          <acceleration>0 0 0 0 -0 0</acceleration>
          <wrench>0 0 0 0 -0 0</wrench>
        </link>
      </model>
      <model name='grey_wall'>
        <pose frame=''>-3.34398 9.61637 0 0 -0 0</pose>
        <scale>1 1 1</scale>
        <link name='link'>
          <pose frame=''>-3.34398 9.61637 1.4 0 -0 0</pose>
          <velocity>0 0 0 0 -0 0</velocity>
          <acceleration>0 0 0 0 -0 0</acceleration>
          <wrench>0 0 0 0 -0 0</wrench>
        </link>
      </model>
      <model name='grey_wall_clone'>
        <pose frame=''>4.15067 9.58036 0 0 -0 0</pose>
        <scale>1 1 1</scale>
        <link name='link'>
          <pose frame=''>4.15067 9.58036 1.4 0 -0 0</pose>
          <velocity>0 0 0 0 -0 0</velocity>
          <acceleration>0 0 0 0 -0 0</acceleration>
          <wrench>0 0 0 0 -0 0</wrench>
        </link>
      </model>
      <model name='grey_wall_clone_0'>
        <pose frame=''>-2.93091 -7.79849 0 0 -0 0</pose>
        <scale>1 1 1</scale>
        <link name='link'>
          <pose frame=''>-2.93091 -7.79849 1.4 0 -0 0</pose>
          <velocity>0 0 0 0 -0 0</velocity>
          <acceleration>0 0 0 0 -0 0</acceleration>
          <wrench>0 0 0 0 -0 0</wrench>
        </link>
      </model>
      <model name='grey_wall_clone_1'>
        <pose frame=''>4.54523 -7.78553 0 0 -0 0</pose>
        <scale>1 1 1</scale>
        <link name='link'>
          <pose frame=''>4.54523 -7.78553 1.4 0 -0 0</pose>
          <velocity>0 0 0 0 -0 0</velocity>
          <acceleration>0 0 0 0 -0 0</acceleration>
          <wrench>0 0 0 0 -0 0</wrench>
        </link>
      </model>
      <model name='grey_wall_clone_2'>
        <pose frame=''>8.11497 -3.92536 0 0 -0 1.57591</pose>
        <scale>1 1 1</scale>
        <link name='link'>
          <pose frame=''>8.11497 -3.92536 1.4 0 -0 1.57591</pose>
          <velocity>0 0 0 0 -0 0</velocity>
          <acceleration>0 0 0 0 -0 0</acceleration>
          <wrench>0 0 0 0 -0 0</wrench>
        </link>
      </model>
      <model name='grey_wall_clone_2_clone'>
        <pose frame=''>8.10329 3.50315 0 0 -0 1.57591</pose>
        <scale>1 1 1</scale>
        <link name='link'>
          <pose frame=''>8.10329 3.50315 1.4 0 -0 1.57591</pose>
          <velocity>0 0 0 0 -0 0</velocity>
          <acceleration>0 0 0 0 -0 0</acceleration>
          <wrench>0 0 0 0 -0 0</wrench>
        </link>
      </model>
      <model name='grey_wall_clone_2_clone_0'>
        <pose frame=''>-6.9781 5.91707 0 0 -0 1.57591</pose>
        <scale>1 1 1</scale>
        <link name='link'>
          <pose frame=''>-6.9781 5.91707 1.4 0 -0 1.57591</pose>
          <velocity>0 0 0 0 -0 0</velocity>
          <acceleration>0 0 0 0 -0 0</acceleration>
          <wrench>0 0 0 0 -0 0</wrench>
        </link>
      </model>
      <model name='grey_wall_clone_2_clone_1'>
        <pose frame=''>-6.92924 -1.57189 0 0 -0 1.57591</pose>
        <scale>1 1 1</scale>
        <link name='link'>
          <pose frame=''>-6.92924 -1.57189 1.4 0 -0 1.57591</pose>
          <velocity>0 0 0 0 -0 0</velocity>
          <acceleration>0 0 0 0 -0 0</acceleration>
          <wrench>0 0 0 0 -0 0</wrench>
        </link>
      </model>
      <model name='ground_plane'>
        <pose frame=''>0 0 0 0 -0 0</pose>
        <scale>1 1 1</scale>
        <link name='link'>
          <pose frame=''>0 0 0 0 -0 0</pose>
          <velocity>0 0 0 0 -0 0</velocity>
          <acceleration>0 0 0 0 -0 0</acceleration>
          <wrench>0 0 0 0 -0 0</wrench>
        </link>
      </model>
      <model name='jersey_barrier'>
        <pose frame=''>6.51418 7.65309 0 0 0 -0.908894</pose>
        <scale>1 1 1</scale>
        <link name='link'>
          <pose frame=''>6.51418 7.65309 0 0 0 -0.908894</pose>
          <velocity>0 0 0 0 -0 0</velocity>
          <acceleration>0 0 0 0 -0 0</acceleration>
          <wrench>0 0 0 0 -0 0</wrench>
        </link>
      </model>
      <model name='jersey_barrier_clone'>
        <pose frame=''>-5.18354 -5.90867 0 0 0 -0.908894</pose>
        <scale>1 1 1</scale>
        <link name='link'>
          <pose frame=''>-5.18354 -5.90867 0 0 0 -0.908894</pose>
          <velocity>0 0 0 0 -0 0</velocity>
          <acceleration>0 0 0 0 -0 0</acceleration>
          <wrench>0 0 0 0 -0 0</wrench>
        </link>
      </model>
      <model name='mobile_base'>
        <pose frame=''>0.012879 0.069039 -0.001131 -4.6e-05 -0.007996 -0.18802</pose>
        <scale>1 1 1</scale>
        <link name='base_footprint'>
          <pose frame=''>0.012879 0.069039 -0.001131 -4.6e-05 -0.007996 -0.18802</pose>
          <velocity>8.4e-05 0.000383 -4.6e-05 0.001384 -0.00029 -0.000666</velocity>
          <acceleration>0.000504 0.00106 -0.007955 1.54016 -0.300291 -0.247984</acceleration>
          <wrench>0.002365 0.00498 -0.037367 0 -0 0</wrench>
        </link>
        <link name='wheel_left_link'>
          <pose frame=''>0.034086 0.182045 0.035043 -1.57095 -0.011334 -0.188019</pose>
          <velocity>0.000149 0.00032 0.000117 0.001384 -0.00029 -0.000666</velocity>
          <acceleration>0.040031 0.106596 0.908164 1.4543 -0.324752 -0.23573</acceleration>
          <wrench>0.0004 0.001066 0.009082 0 -0 0</wrench>
        </link>
        <link name='wheel_right_link'>
          <pose frame=''>-0.00889 -0.043869 0.034866 -1.57093 -0.013062 -0.188017</pose>
          <velocity>-1e-06 0.000349 -0.000208 0.001384 -0.00029 -0.000666</velocity>
          <acceleration>-0.002182 0.120583 -2.1679 1.73313 -0.329783 -0.233799</acceleration>
          <wrench>-2.2e-05 0.001206 -0.021679 0 -0 0</wrench>
        </link>
      </model>
      <model name='polaris_ranger_ev'>
        <pose frame=''>-0.313098 -5.66868 -0.005855 -0.000182 0.0067 -0.827879</pose>
        <scale>1 1 1</scale>
        <link name='brake_pedal'>
          <pose frame=''>0.340532 -5.98112 0.492191 -0.000453 -0.99307 -0.827501</pose>
          <velocity>-0.029655 -0.000413 -0.017526 0.02053 0.011501 -0.008366</velocity>
          <acceleration>-0.230706 -5.64752 6.56839 -1.28222 0.548408 0.592814</acceleration>
          <wrench>-0.023071 -0.564752 0.656839 0 -0 0</wrench>
        </link>
        <link name='chassis'>
          <pose frame=''>-0.313098 -5.66868 -0.005855 -0.000182 0.0067 -0.827879</pose>
          <velocity>-0.02414 0.006515 -0.010217 0.021425 0.012502 -0.009145</velocity>
          <acceleration>-0.313698 -0.320194 6.96902 -0.750419 1.17611 0.414907</acceleration>
          <wrench>-225.862 -230.54 5017.69 0 -0 0</wrench>
        </link>
        <link name='front_left_wheel'>
          <pose frame=''>0.750514 -5.98989 0.320346 1.57262 -0.46997 0.028893</pose>
          <velocity>-0.023094 -0.0202 0.024496 0.063133 -0.072139 -0.000614</velocity>
          <acceleration>-1.50757 -0.848934 42.7842 2.07718 -0.069871 -3.07837</acceleration>
          <wrench>-18.0908 -10.1872 513.41 0 -0 0</wrench>
        </link>
        <link name='front_left_wheel_steering_block'>
          <pose frame=''>0.753494 -6.08976 0.323164 1.57534 0.004475 0.029549</pose>
          <velocity>-0.022739 -0.021953 0.037493 0.043358 0.012817 0.00073</velocity>
          <acceleration>-1.56593 -0.844673 50.4319 -0.01678 0.087914 -1.68118</acceleration>
          <wrench>-1.56593 -0.844673 50.4319 0 -0 0</wrench>
        </link>
        <link name='front_right_wheel'>
          <pose frame=''>-0.024268 -6.85766 0.320224 1.57215 -0.009444 -0.427935</pose>
          <velocity>-0.031622 -0.006611 0.018548 0.020661 -0.098827 6.5e-05</velocity>
          <acceleration>-0.985639 -1.35588 35.0915 -0.735891 0.458867 -2.05812</acceleration>
          <wrench>-11.8277 -16.2705 421.098 0 -0 0</wrench>
        </link>
        <link name='front_right_wheel_steering_block'>
          <pose frame=''>0.017297 -6.76665 0.32396 1.57164 0.006221 -0.427835</pose>
          <velocity>-0.031666 -0.007238 0.034819 0.033517 0.006784 -0.001165</velocity>
          <acceleration>-0.880684 -1.33843 44.275 3.12605 0.854653 0.553663</acceleration>
          <wrench>-0.880684 -1.33843 44.275 0 -0 0</wrench>
        </link>
        <link name='gas_pedal'>
          <pose frame=''>0.197482 -6.01748 0.481024 -0.000338 -0.993228 -0.827593</pose>
          <velocity>-0.031693 0.003035 -0.008481 0.021611 0.0127 -0.009025</velocity>
          <acceleration>-0.17492 -5.52411 3.89848 -1.37444 0.28827 0.555785</acceleration>
          <wrench>-0.017492 -0.552411 0.389848 0 -0 0</wrench>
        </link>
        <link name='hand_brake'>
          <pose frame=''>0.030052 -6.04203 1.04069 -3.14141 -0.066395 2.3137</pose>
          <velocity>-0.014563 -0.019039 -0.022852 0.022164 0.013095 -0.009121</velocity>
          <acceleration>-7.11037 -6.27992 7.07442 -2.96753 1.02038 -3.06526</acceleration>
          <wrench>-7.11037 -6.27992 7.07442 0 -0 0</wrench>
        </link>
        <link name='rear_left_wheel'>
          <pose frame=''>-0.444588 -4.63833 0.320029 -1.57158 -1.14672 2.31456</pose>
          <velocity>-0.010186 0.001043 0.010443 -0.003079 -0.031657 -0.004625</velocity>
          <acceleration>-2.6158 -1.85078 11.4154 0.444545 -0.972368 2.54824</acceleration>
          <wrench>-31.3896 -22.2094 136.985 0 -0 0</wrench>
        </link>
        <link name='rear_right_wheel'>
          <pose frame=''>-1.32837 -5.45006 0.319983 -1.57145 0.712803 2.31328</pose>
          <velocity>-0.017857 0.008542 0.010535 -0.022794 -0.052104 -0.014157</velocity>
          <acceleration>-2.30987 -2.47207 1.81141 1.55616 -0.826268 0.447784</acceleration>
          <wrench>-27.7184 -29.6649 21.7369 0 -0 0</wrench>
        </link>
        <link name='steering_wheel'>
          <pose frame=''>0.163768 -5.74408 1.19152 0.567651 -0.57878 -1.71361</pose>
          <velocity>-0.009766 -0.023691 -0.018114 0.01975 0.01462 -0.006245</velocity>
          <acceleration>-7.52197 -5.95013 9.36391 -1.97646 0.550754 -3.12932</acceleration>
          <wrench>-7.52197 -5.95013 9.36391 0 -0 0</wrench>
        </link>
      </model>
      <light name='sun'>
        <pose frame=''>0 0 10 0 -0 0</pose>
      </light>
    </state>
    <gui fullscreen='0'>
      <camera name='user_camera'>
        <pose frame=''>-26.2889 -0.648191 29.2433 -0 0.753797 0.296201</pose>
        <view_controller>orbit</view_controller>
        <projection_type>perspective</projection_type>
      </camera>
    </gui>
  </world>
</sdf>
